Workbook

Sheet Dashboard
B2: Dashboard · Ventas
B3: Fuente: ventas.xlsx › Reporte · 1,500 registros · generado 09/10/2026 20:47
B5: VENTAS TOTAL | E5: VENTAS PROMEDIO | I5: REGISTROS | L5: ÚLTIMO MES COMPLETO VS ANTERIOR
B6: =SUM(Datos!$H$2:$H$1501) | E6: =IFERROR(AVERAGE(Datos!$H$2:$H$1501),0) | I6: =ROWS(Datos!$A$2:$A$1501) | L6: =IFERROR(Calculos!$D$23/Calculos!$D$22-1,0)
L8: =Calculos!$A$23&": "&TEXT(Calculos!$D$23,"#,##0")
B11: Tendencia de Ventas
B12: Total por mes
B32: Ranking por Categoría | I32: Participación por Región
B33: ="Top 7 de 7 · líder: "&Calculos!$A$29&" ("&TEXT(Calculos!$C$29,"0%")&")" | I33: % de Ventas
B53: Composición por Región | I53: Distribución de Ventas
B54: Ventas por mes, apilado | I54: Número de registros por rango de valor
B74: Categoría × Región | I74: Relación Ventas vs Unidades
B75: Ventas — intensidad de color = mayor valor | I75: Cada punto es un registro
B77: =Calculos!$A$87 | C77: =Calculos!B$87 | D77: =Calculos!C$87 | E77: =Calculos!D$87 | F77: =Calculos!E$87 | G77: =Calculos!F$87
B78: =Calculos!$A$88 | C78: =Calculos!B88 | D78: =Calculos!C88 | E78: =Calculos!D88 | F78: =Calculos!E88 | G78: =Calculos!F88
B79: =Calculos!$A$89 | C79: =Calculos!B89 | D79: =Calculos!C89 | E79: =Calculos!D89 | F79: =Calculos!E89 | G79: =Calculos!F89
B80: =Calculos!$A$90 | C80: =Calculos!B90 | D80: =Calculos!C90 | E80: =Calculos!D90 | F80: =Calculos!E90 | G80: =Calculos!F90
B81: =Calculos!$A$91 | C81: =Calculos!B91 | D81: =Calculos!C91 | E81: =Calculos!D91 | F81: =Calculos!E91 | G81: =Calculos!F91
B82: =Calculos!$A$92 | C82: =Calculos!B92 | D82: =Calculos!C92 | E82: =Calculos!D92 | F82: =Calculos!E92 | G82: =Calculos!F92
B83: =Calculos!$A$93 | C83: =Calculos!B93 | D83: =Calculos!C93 | E83: =Calculos!D93 | F83: =Calculos!E93 | G83: =Calculos!F93
B84: =Calculos!$A$94 | C84: =Calculos!B94 | D84: =Calculos!C94 | E84: =Calculos!D94 | F84: =Calculos!E94 | G84: =Calculos!F94
B95: Ranking por Región | I95: Detalle por Categoría
B96: Top 5 por Ventas | I96: Valor y participación con barras de datos
I98: Categoría | K98: Ventas | N98: % del total
I99: =Calculos!$A$29 | K99: =Calculos!$B$29 | N99: =Calculos!$C$29
I100: =Calculos!$A$30 | K100: =Calculos!$B$30 | N100: =Calculos!$C$30
I101: =Calculos!$A$31 | K101: =Calculos!$B$31 | N101: =Calculos!$C$31
I102: =Calculos!$A$32 | K102: =Calculos!$B$32 | N102: =Calculos!$C$32
I103: =Calculos!$A$33 | K103: =Calculos!$B$33 | N103: =Calculos!$C$33
I104: =Calculos!$A$34 | K104: =Calculos!$B$34 | N104: =Calculos!$C$34
I105: =Calculos!$A$35 | K105: =Calculos!$B$35 | N105: =Calculos!$C$35

Sheet Datos
A1: ID Pedido | B1: Fecha | C1: Región | D1: Categoría | E1: Vendedor | F1: Unidades | G1: Precio unitario | H1: Ventas
A2: 10831 | B2: 45293 | C2: Occidente | D2: Belleza | E2: Luis | F2: 35 | G2: 25 | H2: 609.78
A3: 10076 | B3: 45294 | C3: Oriente | D3: Tecnología | E3: Luis | F3: 20 | G3: 320 | H3: 4460.1
A4: 10353 | B4: 45294 | C4: Norte | D4: Ropa | E4: Pedro | F4: 16 | G4: 25 | H4: 278.76
A5: 11230 | B5: 45294 | C5: Occidente | D5: Libros | E5: Jorge | F5: 22 | G5: 320 | H5: 4906.11
A6: 10230 | B6: 45295 | C6: Centro | D6: Libros | E6: Luis | F6: 11 | G6: 25 | H6: 191.65
A7: 11362 | B7: 45295 | C7: Norte | D7: Tecnología | E7: Ana | F7: 26 | G7: 320 | H7: 5798.13
A8: 10014 | B8: 45295 | C8: Norte | D8: Tecnología | E8: Marta | F8: 36 | G8: 150 | H8: 3763.21
A9: 10141 | B9: 45296 | C9: Norte | D9: Ropa | E9: Pedro | F9: 36 | G9: 150 | H9: 3763.21
A10: 10066 | B10: 45299 | C10: Oriente | D10: Deportes | E10: Marta | F10: 11 | G10: 25 | H10: 191.65
A11: 10885 | B11: 45299 | C11: Oriente | D11: Libros | E11: Ana | F11: 31 | G11: 12.5 | H11: 270.05
A12: 11361 | B12: 45299 | C12: Norte | D12: Ropa | E12: Sofía | F12: 30 | G12: 49.9 | H12: 1043.25
A13: 11117 | B13: 45300 | C13: Centro | D13: Deportes | E13: Marta | F13: 7 | G13: 320 | H13: 1561.04
... A1501: 10225 | B1501: 45931 | C1501: Sur | D1501: Libros | E1501: Ana | F1501: 13 | G1501: 150 | H1501: 1608.75

Sheet Calculos
A1: Ventas por mes | H1: Hoja de apoyo: cada valor es una fórmula sobre la hoja Datos. Si cambias o corriges datos en 'Datos', el Dashboard se actualiza solo.
A2: Período | B2: Desde | C2: Hasta (excl.) | D2: Ventas
A3: Ene 24 | B3: 45292 | C3: 45323 | D3: =SUMIFS(Datos!$H$2:$H$1501,Datos!$B$2:$B$1501,">="&$B3,Datos!$B$2:$B$1501,"<"&$C3)
A4: Feb 24 | B4: 45323 | C4: 45352 | D4: =SUMIFS(Datos!$H$2:$H$1501,Datos!$B$2:$B$1501,">="&$B4,Datos!$B$2:$B$1501,"<"&$C4)
A5: Mar 24 | B5: 45352 | C5: 45383 | D5: =SUMIFS(Datos!$H$2:$H$1501,Datos!$B$2:$B$1501,">="&$B5,Datos!$B$2:$B$1501,"<"&$C5)
A6: Abr 24 | B6: 45383 | C6: 45413 | D6: =SUMIFS(Datos!$H$2:$H$1501,Datos!$B$2:$B$1501,">="&$B6,Datos!$B$2:$B$1501,"<"&$C6)
A7: May 24 | B7: 45413 | C7: 45444 | D7: =SUMIFS(Datos!$H$2:$H$1501,Datos!$B$2:$B$1501,">="&$B7,Datos!$B$2:$B$1501,"<"&$C7)
A8: Jun 24 | B8: 45444 | C8: 45474 | D8: =SUMIFS(Datos!$H$2:$H$1501,Datos!$B$2:$B$1501,">="&$B8,Datos!$B$2:$B$1501,"<"&$C8)
A9: Jul 24 | B9: 45474 | C9: 45505 | D9: =SUMIFS(Datos!$H$2:$H$1501,Datos!$B$2:$B$1501,">="&$B9,Datos!$B$2:$B$1501,"<"&$C9)
A10: Ago 24 | B10: 45505 | C10: 45536 | D10: =SUMIFS(Datos!$H$2:$H$1501,Datos!$B$2:$B$1501,">="&$B10,Datos!$B$2:$B$1501,"<"&$C10)
A11: Sep 24 | B11: 45536 | C11: 45566 | D11: =SUMIFS(Datos!$H$2:$H$1501,Datos!$B$2:$B$1501,">="&$B11,Datos!$B$2:$B$1501,"<"&$C11)
A12: Oct 24 | B12: 45566 | C12: 45597 | D12: =SUMIFS(Datos!$H$2:$H$1501,Datos!$B$2:$B$1501,">="&$B12,Datos!$B$2:$B$1501,"<"&$C12)
A13: Nov 24 | B13: 45597 | C13: 45627 | D13: =SUMIFS(Datos!$H$2:$H$1501,Datos!$B$2:$B$1501,">="&$B13,Datos!$B$2:$B$1501,"<"&$C13)
A14: Dic 24 | B14: 45627 | C14: 45658 | D14: =SUMIFS(Datos!$H$2:$H$1501,Datos!$B$2:$B$1501,">="&$B14,Datos!$B$2:$B$1501,"<"&$C14)
... A24: Oct 25 | B24: 45931 | C24: 45962 | D24: =SUMIFS(Datos!$H$2:$H$1501,Datos!$B$2:$B$1501,">="&$B24,Datos!$B$2:$B$1501,"<"&$C24)
A27: Ranking de Categoría por Ventas
A28: Categoría | B28: Ventas | C28: % del total
A29: Libros | B29: =SUMIFS(Datos!$H$2:$H$1501,Datos!$D$2:$D$1501,$A29) | C29: =IFERROR(B29/SUM(Datos!$H$2:$H$1501),0)
A30: Hogar | B30: =SUMIFS(Datos!$H$2:$H$1501,Datos!$D$2:$D$1501,$A30) | C30: =IFERROR(B30/SUM(Datos!$H$2:$H$1501),0)
A31: Deportes | B31: =SUMIFS(Datos!$H$2:$H$1501,Datos!$D$2:$D$1501,$A31) | C31: =IFERROR(B31/SUM(Datos!$H$2:$H$1501),0)
A32: Ropa | B32: =SUMIFS(Datos!$H$2:$H$1501,Datos!$D$2:$D$1501,$A32) | C32: =IFERROR(B32/SUM(Datos!$H$2:$H$1501),0)
A33: Juguetes | B33: =SUMIFS(Datos!$H$2:$H$1501,Datos!$D$2:$D$1501,$A33) | C33: =IFERROR(B33/SUM(Datos!$H$2:$H$1501),0)
A34: Tecnología | B34: =SUMIFS(Datos!$H$2:$H$1501,Datos!$D$2:$D$1501,$A34) | C34: =IFERROR(B34/SUM(Datos!$H$2:$H$1501),0)
A35: Belleza | B35: =SUMIFS(Datos!$H$2:$H$1501,Datos!$D$2:$D$1501,$A35) | C35: =IFERROR(B35/SUM(Datos!$H$2:$H$1501),0)
A38: Participación por Región
A39: Región | B39: Ventas
A40: Norte | B40: =SUMIFS(Datos!$H$2:$H$1501,Datos!$C$2:$C$1501,$A40)
A41: Centro | B41: =SUMIFS(Datos!$H$2:$H$1501,Datos!$C$2:$C$1501,$A41)
A42: Sur | B42: =SUMIFS(Datos!$H$2:$H$1501,Datos!$C$2:$C$1501,$A42)
A43: Oriente | B43: =SUMIFS(Datos!$H$2:$H$1501,Datos!$C$2:$C$1501,$A43)
A44: Occidente | B44: =SUMIFS(Datos!$H$2:$H$1501,Datos!$C$2:$C$1501,$A44)
A47: Ventas por mes y Región
A48: Período | B48: Norte | C48: Centro | D48: Sur | E48: Oriente | F48: Otros
A49: =A3 | B49: =SUMIFS(Datos!$H$2:$H$1501,Datos!$B$2:$B$1501,">="&$B3,Datos!$B$2:$B$1501,"<"&$C3,Datos!$C$2:$C$1501,B$48) | C49: =SUMIFS(Datos!$H$2:$H$1501,Datos!$B$2:$B$1501,">="&$B3,Datos!$B$2:$B$1501,"<"&$C3,Datos!$C$2:$C$1501,C$48) | D49: =SUMIFS(Datos!$H$2:$H$1501,Datos!$B$2:$B$1501,">="&$B3,Datos!$B$2:$B$1501,"<"&$C3,Datos!$C$2:$C$1501,D$48) | E49: =SUMIFS(Datos!$H$2:$H$1501,Datos!$B$2:$B$1501,">="&$B3,Datos!$B$2:$B$1501,"<"&$C3,Datos!$C$2:$C$1501,E$48) | F49: =D3-SUM(B49:E49)
A50: =A4 | B50: =SUMIFS(Datos!$H$2:$H$1501,Datos!$B$2:$B$1501,">="&$B4,Datos!$B$2:$B$1501,"<"&$C4,Datos!$C$2:$C$1501,B$48) | C50: =SUMIFS(Datos!$H$2:$H$1501,Datos!$B$2:$B$1501,">="&$B4,Datos!$B$2:$B$1501,"<"&$C4,Datos!$C$2:$C$1501,C$48) | D50: =SUMIFS(Datos!$H$2:$H$1501,Datos!$B$2:$B$1501,">="&$B4,Datos!$B$2:$B$1501,"<"&$C4,Datos!$C$2:$C$1501,D$48) | E50: =SUMIFS(Datos!$H$2:$H$1501,Datos!$B$2:$B$1501,">="&$B4,Datos!$B$2:$B$1501,"<"&$C4,Datos!$C$2:$C$1501,E$48) | F50: =D4-SUM(B50:E50)
A51: =A5 | B51: =SUMIFS(Datos!$H$2:$H$1501,Datos!$B$2:$B$1501,">="&$B5,Datos!$B$2:$B$1501,"<"&$C5,Datos!$C$2:$C$1501,B$48) | C51: =SUMIFS(Datos!$H$2:$H$1501,Datos!$B$2:$B$1501,">="&$B5,Datos!$B$2:$B$1501,"<"&$C5,Datos!$C$2:$C$1501,C$48) | D51: =SUMIFS(Datos!$H$2:$H$1501,Datos!$B$2:$B$1501,">="&$B5,Datos!$B$2:$B$1501,"<"&$C5,Datos!$C$2:$C$1501,D$48) | E51: =SUMIFS(Datos!$H$2:$H$1501,Datos!$B$2:$B$1501,">="&$B5,Datos!$B$2:$B$1501,"<"&$C5,Datos!$C$2:$C$1501,E$48) | F51: =D5-SUM(B51:E51)
A52: =A6 | B52: =SUMIFS(Datos!$H$2:$H$1501,Datos!$B$2:$B$1501,">="&$B6,Datos!$B$2:$B$1501,"<"&$C6,Datos!$C$2:$C$1501,B$48) | C52: =SUMIFS(Datos!$H$2:$H$1501,Datos!$B$2:$B$1501,">="&$B6,Datos!$B$2:$B$1501,"<"&$C6,Datos!$C$2:$C$1501,C$48) | D52: =SUMIFS(Datos!$H$2:$H$1501,Datos!$B$2:$B$1501,">="&$B6,Datos!$B$2:$B$1501,"<"&$C6,Datos!$C$2:$C$1501,D$48) | E52: =SUMIFS(Datos!$H$2:$H$1501,Datos!$B$2:$B$1501,">="&$B6,Datos!$B$2:$B$1501,"<"&$C6,Datos!$C$2:$C$1501,E$48) | F52: =D6-SUM(B52:E52)
A53: =A7 | B53: =SUMIFS(Datos!$H$2:$H$1501,Datos!$B$2:$B$1501,">="&$B7,Datos!$B$2:$B$1501,"<"&$C7,Datos!$C$2:$C$1501,B$48) | C53: =SUMIFS(Datos!$H$2:$H$1501,Datos!$B$2:$B$1501,">="&$B7,Datos!$B$2:$B$1501,"<"&$C7,Datos!$C$2:$C$1501,C$48) | D53: =SUMIFS(Datos!$H$2:$H$1501,Datos!$B$2:$B$1501,">="&$B7,Datos!$B$2:$B$1501,"<"&$C7,Datos!$C$2:$C$1501,D$48) | E53: =SUMIFS(Datos!$H$2:$H$1501,Datos!$B$2:$B$1501,">="&$B7,Datos!$B$2:$B$1501,"<"&$C7,Datos!$C$2:$C$1501,E$48) | F53: =D7-SUM(B53:E53)
A54: =A8 | B54: =SUMIFS(Datos!$H$2:$H$1501,Datos!$B$2:$B$1501,">="&$B8,Datos!$B$2:$B$1501,"<"&$C8,Datos!$C$2:$C$1501,B$48) | C54: =SUMIFS(Datos!$H$2:$H$1501,Datos!$B$2:$B$1501,">="&$B8,Datos!$B$2:$B$1501,"<"&$C8,Datos!$C$2:$C$1501,C$48) | D54: =SUMIFS(Datos!$H$2:$H$1501,Datos!$B$2:$B$1501,">="&$B8,Datos!$B$2:$B$1501,"<"&$C8,Datos!$C$2:$C$1501,D$48) | E54: =SUMIFS(Datos!$H$2:$H$1501,Datos!$B$2:$B$1501,">="&$B8,Datos!$B$2:$B$1501,"<"&$C8,Datos!$C$2:$C$1501,E$48) | F54: =D8-SUM(B54:E54)
A55: =A9 | B55: =SUMIFS(Datos!$H$2:$H$1501,Datos!$B$2:$B$1501,">="&$B9,Datos!$B$2:$B$1501,"<"&$C9,Datos!$C$2:$C$1501,B$48) | C55: =SUMIFS(Datos!$H$2:$H$1501,Datos!$B$2:$B$1501,">="&$B9,Datos!$B$2:$B$1501,"<"&$C9,Datos!$C$2:$C$1501,C$48) | D55: =SUMIFS(Datos!$H$2:$H$1501,Datos!$B$2:$B$1501,">="&$B9,Datos!$B$2:$B$1501,"<"&$C9,Datos!$C$2:$C$1501,D$48) | E55: =SUMIFS(Datos!$H$2:$H$1501,Datos!$B$2:$B$1501,">="&$B9,Datos!$B$2:$B$1501,"<"&$C9,Datos!$C$2:$C$1501,E$48) | F55: =D9-SUM(B55:E55)
...

Sheet Acerca de
A1: Cómo se interpretaron los datos
A3: Archivo de origen | B3: ventas.xlsx › Reporte
A4: Registros analizados | B4: 1500
A5: Medida principal | B5: Ventas
A6: Medida secundaria (dispersión) | B6: Unidades
A7: Columna de fecha | B7: Fecha
A8: Categoría principal | B8: Categoría
A9: Categoría secundaria | B9: Región
A10: Categoría de participación | B10: Región
A13: Columna | B13: Rol detectado | C13: Valores únicos | D13: Uso
A14: ID Pedido | B14: Identificador | C14: 1500 | D14: Se ignora en los cálculos (identificador)
A15: Fecha | B15: Fecha | C15: 578 | D15: Eje de tiempo
A16: Región | B16: Categoría | C16: 5 | D16: Agrupación en rankings / participación / mapa de calor
A17: Categoría | B17: Categoría | C17: 7 | D17: Agrupación en rankings / participación / mapa de calor
A18: Vendedor | B18: Categoría | C18: 6
A19: Unidades | B19: Numérica | C19: 39 | D19: Eje X de la dispersión
A20: Precio unitario | B20: Numérica | C20: 6
A21: Ventas | B21: Numérica | C21: 860 | D21: Medida principal: KPIs, tendencia, rankings
A23: ¿No eligió la columna que querías?
A24: Vuelve a ejecutar: python dashboard_excel.py archivo.xlsx --medida "Columna" --categoria "Columna" --fecha "Columna"
