Workbook
Name cMed: Config!$F$6
Name cMed2: Config!$F$7
Name cFecha: Config!$F$8
Name cCat1: Config!$F$9
Name cCat2: Config!$F$10
Name cEtapa: Config!$F$11
Name cDepto: Config!$F$12
Name cCosto: Config!$F$13
Name nFilas: Config!$C$16
Name fMin: Config!$C$17
Name fMax: Config!$C$18
Name gran: Config!$C$19
Name conHora: Config!$C$20
Name total: Config!$C$21
Name n1: Config!$C$22
Name n2: Config!$C$23
Name dona2: Config!$C$24
Name mIni: Config!$C$25
Name nomMed: Config!$C$26
Name tBase: Config!$C$27
Name fTexto: Config!$C$29
Name gIdx: Config!$C$28
Name rMed: INDEX(Datos!$A$2:$AN$1048576,1,MAX(1,cMed)):INDEX(Datos!$A$2:$AN$1048576,MAX(1,nFilas),MAX(1,cMed))
Name rMed2: INDEX(Datos!$A$2:$AN$1048576,1,MAX(1,cMed2)):INDEX(Datos!$A$2:$AN$1048576,MAX(1,nFilas),MAX(1,cMed2))
Name rFecha: INDEX(Datos!$A$2:$AN$1048576,1,MAX(1,cFecha)):INDEX(Datos!$A$2:$AN$1048576,MAX(1,nFilas),MAX(1,cFecha))
Name rCat1: INDEX(Datos!$A$2:$AN$1048576,1,MAX(1,cCat1)):INDEX(Datos!$A$2:$AN$1048576,MAX(1,nFilas),MAX(1,cCat1))
Name rCat2: INDEX(Datos!$A$2:$AN$1048576,1,MAX(1,cCat2)):INDEX(Datos!$A$2:$AN$1048576,MAX(1,nFilas),MAX(1,cCat2))
Name rEtapa: INDEX(Datos!$A$2:$AN$1048576,1,MAX(1,cEtapa)):INDEX(Datos!$A$2:$AN$1048576,MAX(1,nFilas),MAX(1,cEtapa))
Name rDepto: INDEX(Datos!$A$2:$AN$1048576,1,MAX(1,cDepto)):INDEX(Datos!$A$2:$AN$1048576,MAX(1,nFilas),MAX(1,cDepto))
Name rCosto: INDEX(Datos!$A$2:$AN$1048576,1,MAX(1,cCosto)):INDEX(Datos!$A$2:$AN$1048576,MAX(1,nFilas),MAX(1,cCosto))

Sheet Dashboard
B2: =IF(cMed>0,"Dashboard de "&nomMed,"Dashboard de análisis") -> Dashboard de Ventas
B3: =IF(fTexto<>"","⚠ La columna «"&fTexto&"» parece fecha pero está guardada como texto: selecciónala y usa Datos › Texto en columnas › Fecha (DMA). ","")&"Pega tus datos en la hoja Datos (encabezados en la fila 1) · "&FIXED(nFilas,0)&" registros · columnas elegidas en la hoja Config" -> Pega tus datos en la hoja Datos (encabezados en la fila 1) · 2,400 registros · columnas elegidas en la hoja Config
B5: =IF(cMed>0,UPPER(nomMed)&" TOTAL","REGISTROS") -> VENTAS TOTAL | F5: =IF(cMed>0,"REGISTROS",IF(cMed2>0,"PROMEDIO "&UPPER(Config!$E$7),IF(cCat2>0,UPPER(Config!$E$10)&" DISTINTOS","—"))) -> REGISTROS | J5: =IF(cMed>0,"PROMEDIO POR REGISTRO",IF(cEtapa>0,"% "&UPPER(Motor!$CB$14),"—")) -> PROMEDIO POR REGISTRO | N5: =IF(cCosto>0,"MARGEN",IF(AND(cMed>0,cEtapa>0),"% "&UPPER(Motor!$CB$14),IF(cCat1>0,UPPER(Config!$E$9)&" DISTINTOS","—"))) -> MARGEN
B6: =total -> 2006391920 | F6: =IF(cMed>0,IF(ABS(nFilas)>=1000000,FIXED(nFilas/1000000,1)&"M",IF(ABS(nFilas)>=1000,FIXED(nFilas/1000,1)&"K",FIXED(nFilas,IF(ABS(nFilas)<100,1,0)))),IF(cMed2>0,IF(ABS(Motor!$CB$11)>=1000000,FIXED(Motor!$CB$11/1000000,1)&"M",IF(ABS(Motor!$CB$11)>=1000,FIXED(Motor!$CB$11/1000,1)&"K",FIXED(Motor!$CB$11,IF(ABS(Motor!$CB$11)<100,1,0)))),IF(cCat2>0,IF(n2>=40,n2&"+",n2&""),""))) -> 2.4K | J6: =IF(cMed>0,IF(ABS(IFERROR(total/nFilas,0))>=1000000,FIXED(IFERROR(total/nFilas,0)/1000000,1)&"M",IF(ABS(IFERROR(total/nFilas,0))>=1000,FIXED(IFERROR(total/nFilas,0)/1000,1)&"K",FIXED(IFERROR(total/nFilas,0),IF(ABS(IFERROR(total/nFilas,0))<100,1,0)))),IF(cEtapa>0,ROUND(Motor!$CB$15*100,1)&"%","")) -> 836.0K | N6: =IF(cCosto>0,ROUND(Motor!$CB$10*100,1)&"%",IF(AND(cMed>0,cEtapa>0),ROUND(Motor!$CB$15*100,1)&"%",IF(cCat1>0,IF(n1>=40,n1&"+",n1&""),""))) -> 34.9%
B8: =IF(OR(cFecha=0,N(Motor!$CB$4)=0),"",IF(Motor!$CB$3>=Motor!$CB$4,"▲ ","▼ ")&ROUND(ABS(Motor!$CB$3/Motor!$CB$4-1)*100,1)&"% · "&Motor!$CB$9) -> ▲ 7.6% · Sep 25 vs Ago 25 | F8: =IF(cMed>0,IF(OR(cFecha=0,N(Motor!$CB$6)=0),"",IF(Motor!$CB$5>=Motor!$CB$6,"▲ ","▼ ")&ROUND(ABS(Motor!$CB$5/Motor!$CB$6-1)*100,1)&"% · "&Motor!$CB$9),IF(cMed2>0,IF(OR(cFecha=0,N(Motor!$CB$13)=0),"",IF(Motor!$CB$12>=Motor!$CB$13,"▲ ","▼ ")&ROUND(ABS(Motor!$CB$12/Motor!$CB$13-1)*100,1)&"% · "&Motor!$CB$9),"")) -> ▼ 18% · Sep 25 vs Ago 25 | J8: =IF(cMed>0,IF(OR(cFecha=0,N(IFERROR(Motor!$CB$4/Motor!$CB$6,0))=0),"",IF(IFERROR(Motor!$CB$3/Motor!$CB$5,0)>=IFERROR(Motor!$CB$4/Motor!$CB$6,0),"▲ ","▼ ")&ROUND(ABS(IFERROR(Motor!$CB$3/Motor!$CB$5,0)/IFERROR(Motor!$CB$4/Motor!$CB$6,0)-1)*100,1)&"% · "&Motor!$CB$9),IF(cEtapa>0,IF(cFecha=0,"",IF(Motor!$CB$16>=Motor!$CB$17,"▲ ","▼ ")&ROUND(ABS(Motor!$CB$16-Motor!$CB$17)*100,1)&" pp · "&Motor!$CB$9),"")) -> ▲ 31.3% · Sep 25 vs Ago 25 | N8: =IF(cCosto>0,IF(cFecha=0,"",IF(cFecha=0,"",IF(IFERROR((Motor!$CB$3-Motor!$CB$7)/Motor!$CB$3,0)>=IFERROR((Motor!$CB$4-Motor!$CB$8)/Motor!$CB$4,0),"▲ ","▼ ")&ROUND(ABS(IFERROR((Motor!$CB$3-Motor!$CB$7)/Motor!$CB$3,0)-IFERROR((Motor!$CB$4-Motor!$CB$8)/Motor!$CB$4,0))*100,1)&" pp · "&Motor!$CB$9)),IF(AND(cMed>0,cEtapa>0),IF(cFecha=0,"",IF(Motor!$CB$16>=Motor!$CB$17,"▲ ","▼ ")&ROUND(ABS(Motor!$CB$16-Motor!$CB$17)*100,1)&" pp · "&Motor!$CB$9),"")) -> ▲ 2.1 pp · Sep 25 vs Ago 25
B11: ="Tendencia de "&nomMed -> Tendencia de Ventas
B12: =IF(cFecha=0,"⚠ No hay columna de fecha: elígela en Config","Total por "&LOWER(gran)&" · se agrupa solo según el rango de fechas") -> Total por mes · se agrupa solo según el rango de fechas
B31: =IF(cCat1>0,"Ranking por "&Config!$E$9,"Ranking") -> Ranking por Ciudad | J31: ="Participación por "&IF(dona2,Config!$E$10,Config!$E$9) -> Participación por Categoría
B32: =IF(cCat1=0,"⚠ Elige una categoría en Config","Top 10 por "&nomMed&" · líder: "&Motor!$F$3) -> Top 10 por Ventas · líder: Bogotá | J32: =IF(cCat1=0,"⚠ Elige una categoría en Config","% de "&nomMed&" · top 5 + Otros") -> % de Ventas · top 5 + Otros
B51: ="Composición mensual por "&IF(cCat2>0,Config!$E$10,Config!$E$9) -> Composición mensual por Categoría | J51: ="Embudo"&IF(cEtapa>0," por "&Config!$E$11,"") -> Embudo por Etapa
B52: =IF(cFecha=0,"⚠ Necesita columna de fecha (Config)","Últimos 12 meses · barras apiladas") -> Últimos 12 meses · barras apiladas | J52: =IF(cEtapa=0,"⚠ Elige la columna de Etapa en Config (ej. Visita, Carrito, Compra)","Registros por etapa, de mayor a menor · la última es el "&ROUND(IFERROR(LOOKUP(2,1/(Motor!$BU$3:$BU$8<>""),Motor!$BU$3:$BU$8)/Motor!$BU$3,0)*100,1)&"% de la primera") -> Registros por etapa, de mayor a menor · la última es el 23.6% de la primera
B71: ="Matriz: "&IF(cCat1>0,Config!$E$9,"categoría")&" × mes" -> Matriz: Ciudad × mes
B72: =IF(OR(cFecha=0,cCat1=0),"⚠ Necesita fecha y categoría (Config)","Tabla dinámica de "&nomMed&" · últimos 6 meses · color según el valor") -> Tabla dinámica de Ventas · últimos 6 meses · color según el valor
B74: =Motor!AT$2 -> Ciudad | D74: =Motor!AU$2 -> Abr 25 | E74: =Motor!AV$2 -> May 25 | F74: =Motor!AW$2 -> Jun 25 | G74: =Motor!AX$2 -> Jul 25 | H74: =Motor!AY$2 -> Ago 25 | J74: =Motor!AZ$2 -> Sep 25 | K74: =Motor!BA$2 -> Total 6 meses
B75: =Motor!AT3 -> Bogotá | D75: =Motor!AU3 -> 30128910 | E75: =Motor!AV3 -> 32358815 | F75: =Motor!AW3 -> 30920975 | G75: =Motor!AX3 -> 19240210 | H75: =Motor!AY3 -> 31876865 | J75: =Motor!AZ3 -> 35966285 | K75: =Motor!BA3 -> 180492060
B76: =Motor!AT4 -> Medellín | D76: =Motor!AU4 -> 30561990 | E76: =Motor!AV4 -> 13583845 | F76: =Motor!AW4 -> 16902070 | G76: =Motor!AX4 -> 24227440 | H76: =Motor!AY4 -> 15921045 | J76: =Motor!AZ4 -> 12965950 | K76: =Motor!BA4 -> 114162340
B77: =Motor!AT5 -> Cali | D77: =Motor!AU5 -> 8882510 | E77: =Motor!AV5 -> 11355755 | F77: =Motor!AW5 -> 22180125 | G77: =Motor!AX5 -> 16910820 | H77: =Motor!AY5 -> 6750730 | J77: =Motor!AZ5 -> 7444840 | K77: =Motor!BA5 -> 73524780
B78: =Motor!AT6 -> Barranquilla | D78: =Motor!AU6 -> 10780135 | E78: =Motor!AV6 -> 3684460 | F78: =Motor!AW6 -> 20292940 | G78: =Motor!AX6 -> 12220070 | H78: =Motor!AY6 -> 4140075 | J78: =Motor!AZ6 -> 10155800 | K78: =Motor!BA6 -> 61273480
B79: =Motor!AT7 -> Bucaramanga | D79: =Motor!AU7 -> 2680175 | E79: =Motor!AV7 -> 6900755 | F79: =Motor!AW7 -> 6026550 | G79: =Motor!AX7 -> 10151115 | H79: =Motor!AY7 -> 7189000 | J79: =Motor!AZ7 -> 13641035 | K79: =Motor!BA7 -> 46588630
B80: =Motor!AT8 -> Pereira | D80: =Motor!AU8 -> 7650620 | E80: =Motor!AV8 -> 5065660 | F80: =Motor!AW8 -> 10577850 | G80: =Motor!AX8 -> 7159585 | H80: =Motor!AY8 -> 14545595 | J80: =Motor!AZ8 -> 2134000 | K80: =Motor!BA8 -> 47133310
B81: =Motor!AT9 -> Cartagena | D81: =Motor!AU9 -> 6017050 | E81: =Motor!AV9 -> 12168985 | F81: =Motor!AW9 -> 5831180 | G81: =Motor!AX9 -> 14656260 | H81: =Motor!AY9 -> 4863045 | J81: =Motor!AZ9 -> 1270100 | K81: =Motor!BA9 -> 44806620
B82: =Motor!AT10 -> Villavicencio | D82: =Motor!AU10 -> 0 | E82: =Motor!AV10 -> 3200380 | F82: =Motor!AW10 -> 2478015 | G82: =Motor!AX10 -> 7442895 | H82: =Motor!AY10 -> 2106405 | J82: =Motor!AZ10 -> 4088675 | K82: =Motor!BA10 -> 19316370
B83: =Motor!AT11 -> Pasto | D83: =Motor!AU11 -> 3468090 | E83: =Motor!AV11 -> 6147200 | F83: =Motor!AW11 -> 5519700 | G83: =Motor!AX11 -> 4104500 | H83: =Motor!AY11 -> 1007170 | J83: =Motor!AZ11 -> 6914160 | K83: =Motor!BA11 -> 27160820
B84: =Motor!AT12 -> Neiva | D84: =Motor!AU12 -> 432810 | E84: =Motor!AV12 -> 5456970 | F84: =Motor!AW12 -> 2449625 | G84: =Motor!AX12 -> 2408580 | H84: =Motor!AY12 -> 547495 | J84: =Motor!AZ12 -> 1162800 | K84: =Motor!BA12 -> 12458280
B87: ="Mapa de Colombia por "&IF(cDepto>0,Config!$E$12,"departamento") -> Mapa de Colombia por Departamento | J87: ="Top 5 departamentos" -> Top 5 departamentos
B88: =IF(cDepto=0,"⚠ Elige la columna de Departamento en Config","Mosaico por departamento · más oscuro = mayor "&nomMed) -> Mosaico por departamento · más oscuro = mayor Ventas | J88: ="Participación sobre el total de "&nomMed -> Participación sobre el total de Ventas
B89: =N(Motor!$BN$3) -> 0 | G89: =N(Motor!$BN$4) -> 0
B90: =IF(N(Motor!$BN$3)=0,"",Motor!$BN$3) | G90: =IF(N(Motor!$BN$4)=0,"",Motor!$BN$4) | J90: Departamento | M90: =nomMed -> Ventas | P90: %
E91: =N(Motor!$BN$5) -> 174627110 | F91: =N(Motor!$BN$6) -> 0 | G91: =N(Motor!$BN$7) -> 0 | J91: =Motor!$BP$3 -> Bogotá D.C. | M91: =Motor!$BQ$3 -> 554388700 | P91: =IF(Motor!$BQ$3="","",IFERROR(Motor!$BQ$3/total,"")) -> 0.27631127
E92: =IF(N(Motor!$BN$5)=0,"",Motor!$BN$5) -> 174627110 | F92: =IF(N(Motor!$BN$6)=0,"",Motor!$BN$6) | G92: =IF(N(Motor!$BN$7)=0,"",Motor!$BN$7)
D93: =N(Motor!$BN$8) -> 0 | E93: =N(Motor!$BN$9) -> 0 | F93: =N(Motor!$BN$10) -> 128977510 | G93: =N(Motor!$BN$11) -> 0 | J93: =Motor!$BP$4 -> Antioquia | M93: =Motor!$BQ$4 -> 410638375 | P93: =IF(Motor!$BQ$4="","",IFERROR(Motor!$BQ$4/total,"")) -> 0.20466509
D94: =IF(N(Motor!$BN$8)=0,"",Motor!$BN$8) | E94: =IF(N(Motor!$BN$9)=0,"",Motor!$BN$9) | F94: =IF(N(Motor!$BN$10)=0,"",Motor!$BN$10) -> 128977510 | G94: =IF(N(Motor!$BN$11)=0,"",Motor!$BN$11)
C95: =N(Motor!$BN$12) -> 0 | D95: =N(Motor!$BN$13) -> 410638375 | F95: =N(Motor!$BN$14) -> 140976355 | G95: =N(Motor!$BN$15) -> 0 | J95: =Motor!$BP$5 -> Valle del Cauca | M95: =Motor!$BQ$5 -> 260852225 | P95: =IF(Motor!$BQ$5="","",IFERROR(Motor!$BQ$5/total,"")) -> 0.1300106
C96: =IF(N(Motor!$BN$12)=0,"",Motor!$BN$12) | D96: =IF(N(Motor!$BN$13)=0,"",Motor!$BN$13) -> 410638375 | F96: =IF(N(Motor!$BN$14)=0,"",Motor!$BN$14) -> 140976355 | G96: =IF(N(Motor!$BN$15)=0,"",Motor!$BN$15)
C97: =N(Motor!$BN$16) -> 135285040 | D97: =N(Motor!$BN$17) -> 0 | E97: =N(Motor!$BN$18) -> 0 | F97: =N(Motor!$BN$19) -> 0 | G97: =N(Motor!$BN$20) -> 0 | H97: =N(Motor!$BN$21) -> 0 | J97: =Motor!$BP$6 -> Atlántico | M97: =Motor!$BQ$6 -> 174627110 | P97: =IF(Motor!$BQ$6="","",IFERROR(Motor!$BQ$6/total,"")) -> 0.087035393
C98: =IF(N(Motor!$BN$16)=0,"",Motor!$BN$16) -> 135285040 | D98: =IF(N(Motor!$BN$17)=0,"",Motor!$BN$17) | E98: =IF(N(Motor!$BN$18)=0,"",Motor!$BN$18) | F98: =IF(N(Motor!$BN$19)=0,"",Motor!$BN$19) | G98: =IF(N(Motor!$BN$20)=0,"",Motor!$BN$20) | H98: =IF(N(Motor!$BN$21)=0,"",Motor!$BN$21)
C99: =N(Motor!$BN$22) -> 260852225 | D99: =N(Motor!$BN$23) -> 0 | E99: =N(Motor!$BN$24) -> 0 | F99: =N(Motor!$BN$25) -> 554388700 | G99: =N(Motor!$BN$26) -> 83519275 | H99: =N(Motor!$BN$27) -> 0 | J99: =Motor!$BP$7 -> Santander | M99: =Motor!$BQ$7 -> 140976355 | P99: =IF(Motor!$BQ$7="","",IFERROR(Motor!$BQ$7/total,"")) -> 0.070263618
C100: =IF(N(Motor!$BN$22)=0,"",Motor!$BN$22) -> 260852225 | D100: =IF(N(Motor!$BN$23)=0,"",Motor!$BN$23) | E100: =IF(N(Motor!$BN$24)=0,"",Motor!$BN$24) | F100: =IF(N(Motor!$BN$25)=0,"",Motor!$BN$25) -> 554388700 | G100: =IF(N(Motor!$BN$26)=0,"",Motor!$BN$26) -> 83519275 | H100: =IF(N(Motor!$BN$27)=0,"",Motor!$BN$27)
C101: =N(Motor!$BN$28) -> 0 | D101: =N(Motor!$BN$29) -> 48591155 | E101: =N(Motor!$BN$30) -> 0 | F101: =N(Motor!$BN$31) -> 0 | G101: =N(Motor!$BN$32) -> 0
C102: =IF(N(Motor!$BN$28)=0,"",Motor!$BN$28) | D102: =IF(N(Motor!$BN$29)=0,"",Motor!$BN$29) -> 48591155 | E102: =IF(N(Motor!$BN$30)=0,"",Motor!$BN$30) | F102: =IF(N(Motor!$BN$31)=0,"",Motor!$BN$31) | G102: =IF(N(Motor!$BN$32)=0,"",Motor!$BN$32)
...

Sheet Datos
A1: ID Pedido | B1: Fecha | C1: Departamento | D1: Ciudad | E1: Categoría | F1: Canal | G1: Etapa | H1: Unidades | I1: Precio unitario | J1: Ventas | K1: Costo
A2: 10619 | B2: 45383.456 | C2: Bogotá D.C. | D2: Bogotá | E2: Hogar | F2: Web | G2: 3. Pago | H2: 3 | I2: 258900 | J2: 776700 | K2: 485128
A3: 11465 | B3: 45383.538 | C3: Atlántico | D3: Barranquilla | E3: Juguetes | F3: Web | G3: 1. Visita | H3: 2 | I3: 75400 | J3: 150800 | K3: 91694
A4: 10495 | B4: 45383.563 | C4: Valle del Cauca | D4: Cali | E4: Deportes | F4: Web | G4: 1. Visita | H4: 2 | I4: 157000 | J4: 314000 | K4: 231304
A5: 10928 | B5: 45384.537 | C5: Valle del Cauca | D5: Cali | E5: Tecnología | F5: App | G5: 4. Compra | H5: 2 | I5: 719200 | J5: 1438400 | K5: 1052322
A6: 10700 | B6: 45384.54 | C6: Nariño | D6: Pasto | E6: Deportes | F6: Web | G6: 1. Visita | H6: 1 | I6: 136000 | J6: 136000 | K6: 94504
A7: 11314 | B7: 45384.617 | C7: Valle del Cauca | D7: Cali | E7: Hogar | F7: Web | G7: 2. Carrito | H7: 2 | I7: 238200 | J7: 476400 | K7: 340091
A8: 11434 | B8: 45384.759 | C8: Valle del Cauca | D8: Cali | E8: Belleza | F8: App | G8: 1. Visita | H8: 5 | I8: 61800 | J8: 309000 | K8: 175437
A9: 10419 | B9: 45385.831 | C9: Bolívar | D9: Cartagena | E9: Deportes | F9: Web | G9: 3. Pago | H9: 4 | I9: 206000 | J9: 824000 | K9: 568816
A10: 10016 | B10: 45386.376 | C10: Valle del Cauca | D10: Cali | E10: Hogar | F10: App | G10: 1. Visita | H10: 4 | I10: 187900 | J10: 751600 | K10: 433021
A11: 12082 | B11: 45386.466 | C11: Bogotá D.C. | D11: Bogotá | E11: Hogar | F11: App | G11: 1. Visita | H11: 4 | I11: 268600 | J11: 1074400 | K11: 752326
A12: 11210 | B12: 45386.478 | C12: Bogotá D.C. | D12: Bogotá | E12: Hogar | F12: Web | G12: 3. Pago | H12: 4 | I12: 147700 | J12: 590800 | K12: 355322
A13: 10299 | B13: 45386.628 | C13: Meta | D13: Villavicencio | E13: Hogar | F13: Tienda física | G13: 2. Carrito | H13: 5 | I13: 223100 | J13: 1115500 | K13: 665555
... A2401: 12282 | B2401: 45922.936 | C2401: Atlántico | D2401: Barranquilla | E2401: Juguetes | F2401: App | G2401: 2. Carrito | H2401: 4 | I2401: 103700 | J2401: 414800 | K2401: 278656

Sheet Config
B1: Configuración del tablero
B2: La plantilla elige sola las columnas (columna C). Si quieres otra, escógela en la columna amarilla D; para volver a la automática, borra la celda amarilla.
B5: Uso en el tablero | C5: Detección automática | D5: Tu elección (opcional) | E5: En uso | F5: Col.
B6: Medida principal (lo que se suma) | C6: =IF(MAX($I$40:$I$79)>10,INDEX($B$40:$B$79,MATCH(MAX($I$40:$I$79),$I$40:$I$79,0)),"") -> Ventas | E6: =IF(D6<>"",D6,C6) -> Ventas | F6: =IF(E6="",0,IFERROR(MATCH(E6,Datos!$A$1:$AN$1,0),0)) -> 10
B7: Medida secundaria (eje X dispersión) | C7: =IF(MAX($P$40:$P$79)>0,INDEX($B$40:$B$79,MATCH(MAX($P$40:$P$79),$P$40:$P$79,0)),"") -> Unidades | E7: =IF(D7<>"",D7,C7) -> Unidades | F7: =IF(E7="",0,IFERROR(MATCH(E7,Datos!$A$1:$AN$1,0),0)) -> 8
B8: Fecha | C8: =IF(MAX($L$40:$L$79)>0,INDEX($B$40:$B$79,MATCH(MAX($L$40:$L$79),$L$40:$L$79,0)),"") -> Fecha | E8: =IF(D8<>"",D8,C8) -> Fecha | F8: =IF(E8="",0,IFERROR(MATCH(E8,Datos!$A$1:$AN$1,0),0)) -> 2
B9: Categoría principal | C9: =IF(MAX($J$40:$J$79)>0,INDEX($B$40:$B$79,MATCH(MAX($J$40:$J$79),$J$40:$J$79,0)),"") -> Ciudad | E9: =IF(D9<>"",D9,C9) -> Ciudad | F9: =IF(E9="",0,IFERROR(MATCH(E9,Datos!$A$1:$AN$1,0),0)) -> 4
B10: Categoría secundaria | C10: =IF(MAX($Q$40:$Q$79)>0,INDEX($B$40:$B$79,MATCH(MAX($Q$40:$Q$79),$Q$40:$Q$79,0)),"") -> Categoría | E10: =IF(D10<>"",D10,C10) -> Categoría | F10: =IF(E10="",0,IFERROR(MATCH(E10,Datos!$A$1:$AN$1,0),0)) -> 5
B11: Etapa (embudo) | C11: =IF(MAX($M$40:$M$79)>0,INDEX($B$40:$B$79,MATCH(MAX($M$40:$M$79),$M$40:$M$79,0)),"") -> Etapa | E11: =IF(D11<>"",D11,C11) -> Etapa | F11: =IF(E11="",0,IFERROR(MATCH(E11,Datos!$A$1:$AN$1,0),0)) -> 7
B12: Departamento (mapa) | C12: =IF(MAX($N$40:$N$79)>0,INDEX($B$40:$B$79,MATCH(MAX($N$40:$N$79),$N$40:$N$79,0)),"") -> Departamento | E12: =IF(D12<>"",D12,C12) -> Departamento | F12: =IF(E12="",0,IFERROR(MATCH(E12,Datos!$A$1:$AN$1,0),0)) -> 3
B13: Costo (para el margen) | C13: =IF(MAX($R$40:$R$79)>0,INDEX($B$40:$B$79,MATCH(MAX($R$40:$R$79),$R$40:$R$79,0)),"") -> Costo | E13: =IF(D13<>"",D13,C13) -> Costo | F13: =IF(E13="",0,IFERROR(MATCH(E13,Datos!$A$1:$AN$1,0),0)) -> 11
B15: Valores calculados
B16: Filas de datos | C16: =MAX(C40:C79) -> 2400
B17: Fecha mínima | C17: =IF(cFecha>0,MIN(rFecha),"") -> 45383.456
B18: Fecha máxima | C18: =IF(cFecha>0,MAX(rFecha),"") -> 45922.936
B19: Agrupación de la tendencia | C19: =IF(cFecha=0,"",IF(INT(fMax)-INT(fMin)<24,"Día",IF(INT(fMax)-INT(fMin)<168,"Semana",IF(INT(fMax)-INT(fMin)<730,"Mes",IF(INT(fMax)-INT(fMin)<2190,"Trimestre","Año"))))) -> Mes
B20: La fecha incluye hora | C20: =IF(cFecha>0,IFERROR(SUMPRODUCT(--(MOD(rFecha,1)>0))>0,FALSE),FALSE) -> TRUE
B21: Total de la medida | C21: =IF(cMed>0,SUM(rMed),nFilas) -> 2006391920
B22: Valores distintos categoría principal | C22: =SUMPRODUCT(--(Motor!$B$3:$B$42<>"")) -> 10
B23: Valores distintos categoría secundaria | C23: =SUMPRODUCT(--(Motor!$K$3:$K$42<>"")) -> 6
B24: Dona usa la categoría secundaria | C24: =AND(cCat2>0,n2>=2,n2<n1) -> TRUE
B25: Inicio del último mes | C25: =IF(cFecha>0,DATE(YEAR(fMax),MONTH(fMax),1),"") -> 45901
B26: Nombre de la medida | C26: =IF(cMed>0,$E$6,"Registros") -> Ventas
B27: Inicio del primer período | C27: =IF(cFecha=0,"",CHOOSE(gIdx,INT(fMin),INT(fMin)-WEEKDAY(fMin,2)+1,DATE(YEAR(fMin),MONTH(fMin),1),DATE(YEAR(fMin),3*INT((MONTH(fMin)-1)/3)+1,1),DATE(YEAR(fMin),1,1))) -> 45383
B28: Índice de agrupación | C28: =IFERROR(MATCH(gran,{"Día","Semana","Mes","Trimestre","Año"},0),3) -> 3
B29: Columna de fecha guardada como texto | C29: =IF(cFecha>0,"",IFERROR(INDEX($B$40:$B$79,MATCH(TRUE,$S$40:$S$79,0)),""))
B38: Perfil automático de columnas (no editar)
A39: # | B39: Encabezado | C39: Celdas | D39: Numéricas | E39: ¿Fecha? | F39: ¿Número? | G39: Texto norm. | H39: ¿Texto? | I39: P. medida | J39: P. categoría | K39: Distintos (500) | L39: P. fecha | M39: P. etapa | N39: P. depto | O39: P. costo | P39: P. medida 2 | Q39: P. categoría 2 | R39: P. costo 2 | S39: ¿Fecha en texto?
A40: 1 | B40: =IF(INDEX(Datos!$A$1:$AN$1,1,1)="","",INDEX(Datos!$A$1:$AN$1,1,1)&"") -> ID Pedido | C40: =IF(B40="",0,COUNTA(INDEX(Datos!$A$2:$AN$1048576,0,1))) -> 2400 | D40: =IF(B40="",0,COUNT(INDEX(Datos!$A$2:$AN$1048576,0,1))) -> 2400 | E40: =AND(C40>0,D40>=0.9*C40,OR(LEFT(CELL("format",INDEX(Datos!$A$2:$AN$2,1,1)),1)="D",MIN(1,SUMPRODUCT(--ISNUMBER(SEARCH({"fecha","date","periodo","timestamp"},G40))))>0)) -> FALSE | F40: =AND(C40>0,D40>=0.9*C40,NOT(E40),MIN(1,SUMPRODUCT(--ISNUMBER(SEARCH({" id "," id"," cod"," nit "," cedula"," cédula"," telefono"," teléfono"," celular"," sku"," factura"," numero"," número"," nro"," año "," ano "," year"," zip"," postal"," documento"," guia"," guía"," orden"," cuenta"," pedido"," radicado"," consecutivo"," omr"," pob "," placa"," referencia"," ref "},G40))))=0,NOT(AND(K40>=20,K40>=0.95*MIN(500,C40),MIN(1,SUMPRODUCT(--ISNUMBER(SEARCH({"venta","ingreso","monto","importe","total","valor","factur","revenue","sales","amount","utilidad","ganancia","gasto"},G40))))+MIN(1,SUMPRODUCT(--ISNUMBER(SEARCH({"precio","price","unit","costo","cost","promedio","tasa","%","edad","calific","rating","puntaje","porcentaje","satisf","nps","score","nota"},G40))))+MIN(1,SUMPRODUCT(--ISNUMBER(SEARCH({"costo","cost"},G40))))+MIN(1,SUMPRODUCT(--ISNUMBER(SEARCH({" dias"," días","tiempo","demora","duraci","lead"," horas"},G40))))+MIN(1,SUMPRODUCT(--ISNUMBER(SEARCH({"cantidad","unidades","qty","peso","kilos"," kg","volumen","stock","existencia","inventario"},G40))))=0))) -> FALSE | G40: =" "&LOWER(SUBSTITUTE(SUBSTITUTE(SUBSTITUTE(B40,"_"," "),"-"," "),"."," "))&" " -> id pedido | H40: =AND(C40>0,D40<0.5*C40) -> FALSE | I40: =IF(F40,2+10*MIN(1,SUMPRODUCT(--ISNUMBER(SEARCH({"venta","ingreso","monto","importe","total","valor","factur","revenue","sales","amount","utilidad","ganancia","gasto"},G40))))+8*MIN(1,SUMPRODUCT(--ISNUMBER(SEARCH({"cantidad","unidades","qty","peso","kilos"," kg","volumen","stock","existencia","inventario"},G40))))*(1-MIN(1,SUMPRODUCT(--ISNUMBER(SEARCH({"venta","ingreso","monto","importe","total","valor","factur","revenue","sales","amount","utilidad","ganancia","gasto"},G40)))))-MIN(1,SUMPRODUCT(--ISNUMBER(SEARCH({"precio","price","unit","costo","cost","promedio","tasa","%","edad","calific","rating","puntaje","porcentaje","satisf","nps","score","nota"},G40))))+0.040,0) -> 0 | J40: =IF(AND(H40,K40>=2),IF(K40<=40,2+10*MIN(1,SUMPRODUCT(--ISNUMBER(SEARCH({"categor","region","región","producto","linea","línea","segmento","canal","ciudad","tienda","sucursal","vendedor","cliente","tipo","marca","zona","sede","courier","transportadora","oficina","trayecto","motivo","clasifica","proceso"},G40))))+3*AND(K40>=4,K40<=25),0.5+MIN(1,SUMPRODUCT(--ISNUMBER(SEARCH({"categor","region","región","producto","linea","línea","segmento","canal","ciudad","tienda","sucursal","vendedor","cliente","tipo","marca","zona","sede","courier","transportadora","oficina","trayecto","motivo","clasifica","proceso"},G40)))))+0.040,0) -> 0 | K40: =IF(C40>0,SUMPRODUCT((INDEX(Datos!$A$2:$AN$501,0,1)<>"")/COUNTIF(INDEX(Datos!$A$2:$AN$501,0,1),INDEX(Datos!$A$2:$AN$501,0,1)&"")),0) -> 500 | L40: =IF(E40,1+MIN(1,SUMPRODUCT(--ISNUMBER(SEARCH({"fecha","date","periodo","timestamp"},G40))))+0.040,0) -> 0 | M40: =IF(AND(H40,K40>=2,K40<=15),MIN(1,SUMPRODUCT(--ISNUMBER(SEARCH({"etapa","fase","estado","stage","embudo","funnel","paso","status"},G40))))*(1+0.040),0) -> 0 | N40: =IF(H40,MIN(1,SUMPRODUCT(--ISNUMBER(SEARCH({"departamento","depto","dpto","depart"},G40))))*(1+0.040),0) -> 0 | O40: =IF(F40,MIN(1,SUMPRODUCT(--ISNUMBER(SEARCH({"costo","cost"},G40))))*(1+0.040),0) -> 0 | P40: =IF(B40=$E$6,0,I40+5*MIN(1,SUMPRODUCT(--ISNUMBER(SEARCH({" dias"," días","tiempo","demora","duraci","lead"," horas"},G40))))*(I40>0)) -> 0 | Q40: =IF(B40=$E$9,0,J40) -> 0 | R40: =IF(OR(B40=$E$6,INDEX($I$40:$I$79,MAX(1,$F$6))<12),0,O40) -> 0 | S40: =AND(C40>0,D40<0.5*C40,MIN(1,SUMPRODUCT(--ISNUMBER(SEARCH({"fecha","date","periodo","timestamp"},G40))))>0) -> FALSE
A41: 2 | B41: =IF(INDEX(Datos!$A$1:$AN$1,1,2)="","",INDEX(Datos!$A$1:$AN$1,1,2)&"") -> Fecha | C41: =IF(B41="",0,COUNTA(INDEX(Datos!$A$2:$AN$1048576,0,2))) -> 2400 | D41: =IF(B41="",0,COUNT(INDEX(Datos!$A$2:$AN$1048576,0,2))) -> 2400 | E41: =AND(C41>0,D41>=0.9*C41,OR(LEFT(CELL("format",INDEX(Datos!$A$2:$AN$2,1,2)),1)="D",MIN(1,SUMPRODUCT(--ISNUMBER(SEARCH({"fecha","date","periodo","timestamp"},G41))))>0)) -> TRUE | F41: =AND(C41>0,D41>=0.9*C41,NOT(E41),MIN(1,SUMPRODUCT(--ISNUMBER(SEARCH({" id "," id"," cod"," nit "," cedula"," cédula"," telefono"," teléfono"," celular"," sku"," factura"," numero"," número"," nro"," año "," ano "," year"," zip"," postal"," documento"," guia"," guía"," orden"," cuenta"," pedido"," radicado"," consecutivo"," omr"," pob "," placa"," referencia"," ref "},G41))))=0,NOT(AND(K41>=20,K41>=0.95*MIN(500,C41),MIN(1,SUMPRODUCT(--ISNUMBER(SEARCH({"venta","ingreso","monto","importe","total","valor","factur","revenue","sales","amount","utilidad","ganancia","gasto"},G41))))+MIN(1,SUMPRODUCT(--ISNUMBER(SEARCH({"precio","price","unit","costo","cost","promedio","tasa","%","edad","calific","rating","puntaje","porcentaje","satisf","nps","score","nota"},G41))))+MIN(1,SUMPRODUCT(--ISNUMBER(SEARCH({"costo","cost"},G41))))+MIN(1,SUMPRODUCT(--ISNUMBER(SEARCH({" dias"," días","tiempo","demora","duraci","lead"," horas"},G41))))+MIN(1,SUMPRODUCT(--ISNUMBER(SEARCH({"cantidad","unidades","qty","peso","kilos"," kg","volumen","stock","existencia","inventario"},G41))))=0))) -> FALSE | G41: =" "&LOWER(SUBSTITUTE(SUBSTITUTE(SUBSTITUTE(B41,"_"," "),"-"," "),"."," "))&" " -> fecha | H41: =AND(C41>0,D41<0.5*C41) -> FALSE | I41: =IF(F41,2+10*MIN(1,SUMPRODUCT(--ISNUMBER(SEARCH({"venta","ingreso","monto","importe","total","valor","factur","revenue","sales","amount","utilidad","ganancia","gasto"},G41))))+8*MIN(1,SUMPRODUCT(--ISNUMBER(SEARCH({"cantidad","unidades","qty","peso","kilos"," kg","volumen","stock","existencia","inventario"},G41))))*(1-MIN(1,SUMPRODUCT(--ISNUMBER(SEARCH({"venta","ingreso","monto","importe","total","valor","factur","revenue","sales","amount","utilidad","ganancia","gasto"},G41)))))-MIN(1,SUMPRODUCT(--ISNUMBER(SEARCH({"precio","price","unit","costo","cost","promedio","tasa","%","edad","calific","rating","puntaje","porcentaje","satisf","nps","score","nota"},G41))))+0.039,0) -> 0 | J41: =IF(AND(H41,K41>=2),IF(K41<=40,2+10*MIN(1,SUMPRODUCT(--ISNUMBER(SEARCH({"categor","region","región","producto","linea","línea","segmento","canal","ciudad","tienda","sucursal","vendedor","cliente","tipo","marca","zona","sede","courier","transportadora","oficina","trayecto","motivo","clasifica","proceso"},G41))))+3*AND(K41>=4,K41<=25),0.5+MIN(1,SUMPRODUCT(--ISNUMBER(SEARCH({"categor","region","región","producto","linea","línea","segmento","canal","ciudad","tienda","sucursal","vendedor","cliente","tipo","marca","zona","sede","courier","transportadora","oficina","trayecto","motivo","clasifica","proceso"},G41)))))+0.039,0) -> 0 | K41: =IF(C41>0,SUMPRODUCT((INDEX(Datos!$A$2:$AN$501,0,2)<>"")/COUNTIF(INDEX(Datos!$A$2:$AN$501,0,2),INDEX(Datos!$A$2:$AN$501,0,2)&"")),0) -> 500 | L41: =IF(E41,1+MIN(1,SUMPRODUCT(--ISNUMBER(SEARCH({"fecha","date","periodo","timestamp"},G41))))+0.039,0) -> 2.039 | M41: =IF(AND(H41,K41>=2,K41<=15),MIN(1,SUMPRODUCT(--ISNUMBER(SEARCH({"etapa","fase","estado","stage","embudo","funnel","paso","status"},G41))))*(1+0.039),0) -> 0 | N41: =IF(H41,MIN(1,SUMPRODUCT(--ISNUMBER(SEARCH({"departamento","depto","dpto","depart"},G41))))*(1+0.039),0) -> 0 | O41: =IF(F41,MIN(1,SUMPRODUCT(--ISNUMBER(SEARCH({"costo","cost"},G41))))*(1+0.039),0) -> 0 | P41: =IF(B41=$E$6,0,I41+5*MIN(1,SUMPRODUCT(--ISNUMBER(SEARCH({" dias"," días","tiempo","demora","duraci","lead"," horas"},G41))))*(I41>0)) -> 0 | Q41: =IF(B41=$E$9,0,J41) -> 0 | R41: =IF(OR(B41=$E$6,INDEX($I$40:$I$79,MAX(1,$F$6))<12),0,O41) -> 0 | S41: =AND(C41>0,D41<0.5*C41,MIN(1,SUMPRODUCT(--ISNUMBER(SEARCH({"fecha","date","periodo","timestamp"},G41))))>0) -> FALSE
A42: 3 | B42: =IF(INDEX(Datos!$A$1:$AN$1,1,3)="","",INDEX(Datos!$A$1:$AN$1,1,3)&"") -> Departamento | C42: =IF(B42="",0,COUNTA(INDEX(Datos!$A$2:$AN$1048576,0,3))) -> 2400 | D42: =IF(B42="",0,COUNT(INDEX(Datos!$A$2:$AN$1048576,0,3))) -> 0 | E42: =AND(C42>0,D42>=0.9*C42,OR(LEFT(CELL("format",INDEX(Datos!$A$2:$AN$2,1,3)),1)="D",MIN(1,SUMPRODUCT(--ISNUMBER(SEARCH({"fecha","date","periodo","timestamp"},G42))))>0)) -> FALSE | F42: =AND(C42>0,D42>=0.9*C42,NOT(E42),MIN(1,SUMPRODUCT(--ISNUMBER(SEARCH({" id "," id"," cod"," nit "," cedula"," cédula"," telefono"," teléfono"," celular"," sku"," factura"," numero"," número"," nro"," año "," ano "," year"," zip"," postal"," documento"," guia"," guía"," orden"," cuenta"," pedido"," radicado"," consecutivo"," omr"," pob "," placa"," referencia"," ref "},G42))))=0,NOT(AND(K42>=20,K42>=0.95*MIN(500,C42),MIN(1,SUMPRODUCT(--ISNUMBER(SEARCH({"venta","ingreso","monto","importe","total","valor","factur","revenue","sales","amount","utilidad","ganancia","gasto"},G42))))+MIN(1,SUMPRODUCT(--ISNUMBER(SEARCH({"precio","price","unit","costo","cost","promedio","tasa","%","edad","calific","rating","puntaje","porcentaje","satisf","nps","score","nota"},G42))))+MIN(1,SUMPRODUCT(--ISNUMBER(SEARCH({"costo","cost"},G42))))+MIN(1,SUMPRODUCT(--ISNUMBER(SEARCH({" dias"," días","tiempo","demora","duraci","lead"," horas"},G42))))+MIN(1,SUMPRODUCT(--ISNUMBER(SEARCH({"cantidad","unidades","qty","peso","kilos"," kg","volumen","stock","existencia","inventario"},G42))))=0))) -> FALSE | G42: =" "&LOWER(SUBSTITUTE(SUBSTITUTE(SUBSTITUTE(B42,"_"," "),"-"," "),"."," "))&" " -> departamento | H42: =AND(C42>0,D42<0.5*C42) -> TRUE | I42: =IF(F42,2+10*MIN(1,SUMPRODUCT(--ISNUMBER(SEARCH({"venta","ingreso","monto","importe","total","valor","factur","revenue","sales","amount","utilidad","ganancia","gasto"},G42))))+8*MIN(1,SUMPRODUCT(--ISNUMBER(SEARCH({"cantidad","unidades","qty","peso","kilos"," kg","volumen","stock","existencia","inventario"},G42))))*(1-MIN(1,SUMPRODUCT(--ISNUMBER(SEARCH({"venta","ingreso","monto","importe","total","valor","factur","revenue","sales","amount","utilidad","ganancia","gasto"},G42)))))-MIN(1,SUMPRODUCT(--ISNUMBER(SEARCH({"precio","price","unit","costo","cost","promedio","tasa","%","edad","calific","rating","puntaje","porcentaje","satisf","nps","score","nota"},G42))))+0.038,0) -> 0 | J42: =IF(AND(H42,K42>=2),IF(K42<=40,2+10*MIN(1,SUMPRODUCT(--ISNUMBER(SEARCH({"categor","region","región","producto","linea","línea","segmento","canal","ciudad","tienda","sucursal","vendedor","cliente","tipo","marca","zona","sede","courier","transportadora","oficina","trayecto","motivo","clasifica","proceso"},G42))))+3*AND(K42>=4,K42<=25),0.5+MIN(1,SUMPRODUCT(--ISNUMBER(SEARCH({"categor","region","región","producto","linea","línea","segmento","canal","ciudad","tienda","sucursal","vendedor","cliente","tipo","marca","zona","sede","courier","transportadora","oficina","trayecto","motivo","clasifica","proceso"},G42)))))+0.038,0) -> 5.038 | K42: =IF(C42>0,SUMPRODUCT((INDEX(Datos!$A$2:$AN$501,0,3)<>"")/COUNTIF(INDEX(Datos!$A$2:$AN$501,0,3),INDEX(Datos!$A$2:$AN$501,0,3)&"")),0) -> 10 | L42: =IF(E42,1+MIN(1,SUMPRODUCT(--ISNUMBER(SEARCH({"fecha","date","periodo","timestamp"},G42))))+0.038,0) -> 0 | M42: =IF(AND(H42,K42>=2,K42<=15),MIN(1,SUMPRODUCT(--ISNUMBER(SEARCH({"etapa","fase","estado","stage","embudo","funnel","paso","status"},G42))))*(1+0.038),0) -> 0 | N42: =IF(H42,MIN(1,SUMPRODUCT(--ISNUMBER(SEARCH({"departamento","depto","dpto","depart"},G42))))*(1+0.038),0) -> 1.038 | O42: =IF(F42,MIN(1,SUMPRODUCT(--ISNUMBER(SEARCH({"costo","cost"},G42))))*(1+0.038),0) -> 0 | P42: =IF(B42=$E$6,0,I42+5*MIN(1,SUMPRODUCT(--ISNUMBER(SEARCH({" dias"," días","tiempo","demora","duraci","lead"," horas"},G42))))*(I42>0)) -> 0 | Q42: =IF(B42=$E$9,0,J42) -> 5.038 | R42: =IF(OR(B42=$E$6,INDEX($I$40:$I$79,MAX(1,$F$6))<12),0,O42) -> 0 | S42: =AND(C42>0,D42<0.5*C42,MIN(1,SUMPRODUCT(--ISNUMBER(SEARCH({"fecha","date","periodo","timestamp"},G42))))>0) -> FALSE
A43: 4 | B43: =IF(INDEX(Datos!$A$1:$AN$1,1,4)="","",INDEX(Datos!$A$1:$AN$1,1,4)&"") -> Ciudad | C43: =IF(B43="",0,COUNTA(INDEX(Datos!$A$2:$AN$1048576,0,4))) -> 2400 | D43: =IF(B43="",0,COUNT(INDEX(Datos!$A$2:$AN$1048576,0,4))) -> 0 | E43: =AND(C43>0,D43>=0.9*C43,OR(LEFT(CELL("format",INDEX(Datos!$A$2:$AN$2,1,4)),1)="D",MIN(1,SUMPRODUCT(--ISNUMBER(SEARCH({"fecha","date","periodo","timestamp"},G43))))>0)) -> FALSE | F43: =AND(C43>0,D43>=0.9*C43,NOT(E43),MIN(1,SUMPRODUCT(--ISNUMBER(SEARCH({" id "," id"," cod"," nit "," cedula"," cédula"," telefono"," teléfono"," celular"," sku"," factura"," numero"," número"," nro"," año "," ano "," year"," zip"," postal"," documento"," guia"," guía"," orden"," cuenta"," pedido"," radicado"," consecutivo"," omr"," pob "," placa"," referencia"," ref "},G43))))=0,NOT(AND(K43>=20,K43>=0.95*MIN(500,C43),MIN(1,SUMPRODUCT(--ISNUMBER(SEARCH({"venta","ingreso","monto","importe","total","valor","factur","revenue","sales","amount","utilidad","ganancia","gasto"},G43))))+MIN(1,SUMPRODUCT(--ISNUMBER(SEARCH({"precio","price","unit","costo","cost","promedio","tasa","%","edad","calific","rating","puntaje","porcentaje","satisf","nps","score","nota"},G43))))+MIN(1,SUMPRODUCT(--ISNUMBER(SEARCH({"costo","cost"},G43))))+MIN(1,SUMPRODUCT(--ISNUMBER(SEARCH({" dias"," días","tiempo","demora","duraci","lead"," horas"},G43))))+MIN(1,SUMPRODUCT(--ISNUMBER(SEARCH({"cantidad","unidades","qty","peso","kilos"," kg","volumen","stock","existencia","inventario"},G43))))=0))) -> FALSE | G43: =" "&LOWER(SUBSTITUTE(SUBSTITUTE(SUBSTITUTE(B43,"_"," "),"-"," "),"."," "))&" " -> ciudad | H43: =AND(C43>0,D43<0.5*C43) -> TRUE | I43: =IF(F43,2+10*MIN(1,SUMPRODUCT(--ISNUMBER(SEARCH({"venta","ingreso","monto","importe","total","valor","factur","revenue","sales","amount","utilidad","ganancia","gasto"},G43))))+8*MIN(1,SUMPRODUCT(--ISNUMBER(SEARCH({"cantidad","unidades","qty","peso","kilos"," kg","volumen","stock","existencia","inventario"},G43))))*(1-MIN(1,SUMPRODUCT(--ISNUMBER(SEARCH({"venta","ingreso","monto","importe","total","valor","factur","revenue","sales","amount","utilidad","ganancia","gasto"},G43)))))-MIN(1,SUMPRODUCT(--ISNUMBER(SEARCH({"precio","price","unit","costo","cost","promedio","tasa","%","edad","calific","rating","puntaje","porcentaje","satisf","nps","score","nota"},G43))))+0.037,0) -> 0 | J43: =IF(AND(H43,K43>=2),IF(K43<=40,2+10*MIN(1,SUMPRODUCT(--ISNUMBER(SEARCH({"categor","region","región","producto","linea","línea","segmento","canal","ciudad","tienda","sucursal","vendedor","cliente","tipo","marca","zona","sede","courier","transportadora","oficina","trayecto","motivo","clasifica","proceso"},G43))))+3*AND(K43>=4,K43<=25),0.5+MIN(1,SUMPRODUCT(--ISNUMBER(SEARCH({"categor","region","región","producto","linea","línea","segmento","canal","ciudad","tienda","sucursal","vendedor","cliente","tipo","marca","zona","sede","courier","transportadora","oficina","trayecto","motivo","clasifica","proceso"},G43)))))+0.037,0) -> 15.037 | K43: =IF(C43>0,SUMPRODUCT((INDEX(Datos!$A$2:$AN$501,0,4)<>"")/COUNTIF(INDEX(Datos!$A$2:$AN$501,0,4),INDEX(Datos!$A$2:$AN$501,0,4)&"")),0) -> 10 | L43: =IF(E43,1+MIN(1,SUMPRODUCT(--ISNUMBER(SEARCH({"fecha","date","periodo","timestamp"},G43))))+0.037,0) -> 0 | M43: =IF(AND(H43,K43>=2,K43<=15),MIN(1,SUMPRODUCT(--ISNUMBER(SEARCH({"etapa","fase","estado","stage","embudo","funnel","paso","status"},G43))))*(1+0.037),0) -> 0 | N43: =IF(H43,MIN(1,SUMPRODUCT(--ISNUMBER(SEARCH({"departamento","depto","dpto","depart"},G43))))*(1+0.037),0) -> 0 | O43: =IF(F43,MIN(1,SUMPRODUCT(--ISNUMBER(SEARCH({"costo","cost"},G43))))*(1+0.037),0) -> 0 | P43: =IF(B43=$E$6,0,I43+5*MIN(1,SUMPRODUCT(--ISNUMBER(SEARCH({" dias"," días","tiempo","demora","duraci","lead"," horas"},G43))))*(I43>0)) -> 0 | Q43: =IF(B43=$E$9,0,J43) -> 0 | R43: =IF(OR(B43=$E$6,INDEX($I$40:$I$79,MAX(1,$F$6))<12),0,O43) -> 0 | S43: =AND(C43>0,D43<0.5*C43,MIN(1,SUMPRODUCT(--ISNUMBER(SEARCH({"fecha","date","periodo","timestamp"},G43))))>0) -> FALSE
A44: 5 | B44: =IF(INDEX(Datos!$A$1:$AN$1,1,5)="","",INDEX(Datos!$A$1:$AN$1,1,5)&"") -> Categoría | C44: =IF(B44="",0,COUNTA(INDEX(Datos!$A$2:$AN$1048576,0,5))) -> 2400 | D44: =IF(B44="",0,COUNT(INDEX(Datos!$A$2:$AN$1048576,0,5))) -> 0 | E44: =AND(C44>0,D44>=0.9*C44,OR(LEFT(CELL("format",INDEX(Datos!$A$2:$AN$2,1,5)),1)="D",MIN(1,SUMPRODUCT(--ISNUMBER(SEARCH({"fecha","date","periodo","timestamp"},G44))))>0)) -> FALSE | F44: =AND(C44>0,D44>=0.9*C44,NOT(E44),MIN(1,SUMPRODUCT(--ISNUMBER(SEARCH({" id "," id"," cod"," nit "," cedula"," cédula"," telefono"," teléfono"," celular"," sku"," factura"," numero"," número"," nro"," año "," ano "," year"," zip"," postal"," documento"," guia"," guía"," orden"," cuenta"," pedido"," radicado"," consecutivo"," omr"," pob "," placa"," referencia"," ref "},G44))))=0,NOT(AND(K44>=20,K44>=0.95*MIN(500,C44),MIN(1,SUMPRODUCT(--ISNUMBER(SEARCH({"venta","ingreso","monto","importe","total","valor","factur","revenue","sales","amount","utilidad","ganancia","gasto"},G44))))+MIN(1,SUMPRODUCT(--ISNUMBER(SEARCH({"precio","price","unit","costo","cost","promedio","tasa","%","edad","calific","rating","puntaje","porcentaje","satisf","nps","score","nota"},G44))))+MIN(1,SUMPRODUCT(--ISNUMBER(SEARCH({"costo","cost"},G44))))+MIN(1,SUMPRODUCT(--ISNUMBER(SEARCH({" dias"," días","tiempo","demora","duraci","lead"," horas"},G44))))+MIN(1,SUMPRODUCT(--ISNUMBER(SEARCH({"cantidad","unidades","qty","peso","kilos"," kg","volumen","stock","existencia","inventario"},G44))))=0))) -> FALSE | G44: =" "&LOWER(SUBSTITUTE(SUBSTITUTE(SUBSTITUTE(B44,"_"," "),"-"," "),"."," "))&" " -> categoría | H44: =AND(C44>0,D44<0.5*C44) -> TRUE | I44: =IF(F44,2+10*MIN(1,SUMPRODUCT(--ISNUMBER(SEARCH({"venta","ingreso","monto","importe","total","valor","factur","revenue","sales","amount","utilidad","ganancia","gasto"},G44))))+8*MIN(1,SUMPRODUCT(--ISNUMBER(SEARCH({"cantidad","unidades","qty","peso","kilos"," kg","volumen","stock","existencia","inventario"},G44))))*(1-MIN(1,SUMPRODUCT(--ISNUMBER(SEARCH({"venta","ingreso","monto","importe","total","valor","factur","revenue","sales","amount","utilidad","ganancia","gasto"},G44)))))-MIN(1,SUMPRODUCT(--ISNUMBER(SEARCH({"precio","price","unit","costo","cost","promedio","tasa","%","edad","calific","rating","puntaje","porcentaje","satisf","nps","score","nota"},G44))))+0.036,0) -> 0 | J44: =IF(AND(H44,K44>=2),IF(K44<=40,2+10*MIN(1,SUMPRODUCT(--ISNUMBER(SEARCH({"categor","region","región","producto","linea","línea","segmento","canal","ciudad","tienda","sucursal","vendedor","cliente","tipo","marca","zona","sede","courier","transportadora","oficina","trayecto","motivo","clasifica","proceso"},G44))))+3*AND(K44>=4,K44<=25),0.5+MIN(1,SUMPRODUCT(--ISNUMBER(SEARCH({"categor","region","región","producto","linea","línea","segmento","canal","ciudad","tienda","sucursal","vendedor","cliente","tipo","marca","zona","sede","courier","transportadora","oficina","trayecto","motivo","clasifica","proceso"},G44)))))+0.036,0) -> 15.036 | K44: =IF(C44>0,SUMPRODUCT((INDEX(Datos!$A$2:$AN$501,0,5)<>"")/COUNTIF(INDEX(Datos!$A$2:$AN$501,0,5),INDEX(Datos!$A$2:$AN$501,0,5)&"")),0) -> 6 | L44: =IF(E44,1+MIN(1,SUMPRODUCT(--ISNUMBER(SEARCH({"fecha","date","periodo","timestamp"},G44))))+0.036,0) -> 0 | M44: =IF(AND(H44,K44>=2,K44<=15),MIN(1,SUMPRODUCT(--ISNUMBER(SEARCH({"etapa","fase","estado","stage","embudo","funnel","paso","status"},G44))))*(1+0.036),0) -> 0 | N44: =IF(H44,MIN(1,SUMPRODUCT(--ISNUMBER(SEARCH({"departamento","depto","dpto","depart"},G44))))*(1+0.036),0) -> 0 | O44: =IF(F44,MIN(1,SUMPRODUCT(--ISNUMBER(SEARCH({"costo","cost"},G44))))*(1+0.036),0) -> 0 | P44: =IF(B44=$E$6,0,I44+5*MIN(1,SUMPRODUCT(--ISNUMBER(SEARCH({" dias"," días","tiempo","demora","duraci","lead"," horas"},G44))))*(I44>0)) -> 0 | Q44: =IF(B44=$E$9,0,J44) -> 15.036 | R44: =IF(OR(B44=$E$6,INDEX($I$40:$I$79,MAX(1,$F$6))<12),0,O44) -> 0 | S44: =AND(C44>0,D44<0.5*C44,MIN(1,SUMPRODUCT(--ISNUMBER(SEARCH({"fecha","date","periodo","timestamp"},G44))))>0) -> FALSE
A45: 6 | B45: =IF(INDEX(Datos!$A$1:$AN$1,1,6)="","",INDEX(Datos!$A$1:$AN$1,1,6)&"") -> Canal | C45: =IF(B45="",0,COUNTA(INDEX(Datos!$A$2:$AN$1048576,0,6))) -> 2400 | D45: =IF(B45="",0,COUNT(INDEX(Datos!$A$2:$AN$1048576,0,6))) -> 0 | E45: =AND(C45>0,D45>=0.9*C45,OR(LEFT(CELL("format",INDEX(Datos!$A$2:$AN$2,1,6)),1)="D",MIN(1,SUMPRODUCT(--ISNUMBER(SEARCH({"fecha","date","periodo","timestamp"},G45))))>0)) -> FALSE | F45: =AND(C45>0,D45>=0.9*C45,NOT(E45),MIN(1,SUMPRODUCT(--ISNUMBER(SEARCH({" id "," id"," cod"," nit "," cedula"," cédula"," telefono"," teléfono"," celular"," sku"," factura"," numero"," número"," nro"," año "," ano "," year"," zip"," postal"," documento"," guia"," guía"," orden"," cuenta"," pedido"," radicado"," consecutivo"," omr"," pob "," placa"," referencia"," ref "},G45))))=0,NOT(AND(K45>=20,K45>=0.95*MIN(500,C45),MIN(1,SUMPRODUCT(--ISNUMBER(SEARCH({"venta","ingreso","monto","importe","total","valor","factur","revenue","sales","amount","utilidad","ganancia","gasto"},G45))))+MIN(1,SUMPRODUCT(--ISNUMBER(SEARCH({"precio","price","unit","costo","cost","promedio","tasa","%","edad","calific","rating","puntaje","porcentaje","satisf","nps","score","nota"},G45))))+MIN(1,SUMPRODUCT(--ISNUMBER(SEARCH({"costo","cost"},G45))))+MIN(1,SUMPRODUCT(--ISNUMBER(SEARCH({" dias"," días","tiempo","demora","duraci","lead"," horas"},G45))))+MIN(1,SUMPRODUCT(--ISNUMBER(SEARCH({"cantidad","unidades","qty","peso","kilos"," kg","volumen","stock","existencia","inventario"},G45))))=0))) -> FALSE | G45: =" "&LOWER(SUBSTITUTE(SUBSTITUTE(SUBSTITUTE(B45,"_"," "),"-"," "),"."," "))&" " -> canal | H45: =AND(C45>0,D45<0.5*C45) -> TRUE | I45: =IF(F45,2+10*MIN(1,SUMPRODUCT(--ISNUMBER(SEARCH({"venta","ingreso","monto","importe","total","valor","factur","revenue","sales","amount","utilidad","ganancia","gasto"},G45))))+8*MIN(1,SUMPRODUCT(--ISNUMBER(SEARCH({"cantidad","unidades","qty","peso","kilos"," kg","volumen","stock","existencia","inventario"},G45))))*(1-MIN(1,SUMPRODUCT(--ISNUMBER(SEARCH({"venta","ingreso","monto","importe","total","valor","factur","revenue","sales","amount","utilidad","ganancia","gasto"},G45)))))-MIN(1,SUMPRODUCT(--ISNUMBER(SEARCH({"precio","price","unit","costo","cost","promedio","tasa","%","edad","calific","rating","puntaje","porcentaje","satisf","nps","score","nota"},G45))))+0.035,0) -> 0 | J45: =IF(AND(H45,K45>=2),IF(K45<=40,2+10*MIN(1,SUMPRODUCT(--ISNUMBER(SEARCH({"categor","region","región","producto","linea","línea","segmento","canal","ciudad","tienda","sucursal","vendedor","cliente","tipo","marca","zona","sede","courier","transportadora","oficina","trayecto","motivo","clasifica","proceso"},G45))))+3*AND(K45>=4,K45<=25),0.5+MIN(1,SUMPRODUCT(--ISNUMBER(SEARCH({"categor","region","región","producto","linea","línea","segmento","canal","ciudad","tienda","sucursal","vendedor","cliente","tipo","marca","zona","sede","courier","transportadora","oficina","trayecto","motivo","clasifica","proceso"},G45)))))+0.035,0) -> 15.035 | K45: =IF(C45>0,SUMPRODUCT((INDEX(Datos!$A$2:$AN$501,0,6)<>"")/COUNTIF(INDEX(Datos!$A$2:$AN$501,0,6),INDEX(Datos!$A$2:$AN$501,0,6)&"")),0) -> 4 | L45: =IF(E45,1+MIN(1,SUMPRODUCT(--ISNUMBER(SEARCH({"fecha","date","periodo","timestamp"},G45))))+0.035,0) -> 0 | M45: =IF(AND(H45,K45>=2,K45<=15),MIN(1,SUMPRODUCT(--ISNUMBER(SEARCH({"etapa","fase","estado","stage","embudo","funnel","paso","status"},G45))))*(1+0.035),0) -> 0 | N45: =IF(H45,MIN(1,SUMPRODUCT(--ISNUMBER(SEARCH({"departamento","depto","dpto","depart"},G45))))*(1+0.035),0) -> 0 | O45: =IF(F45,MIN(1,SUMPRODUCT(--ISNUMBER(SEARCH({"costo","cost"},G45))))*(1+0.035),0) -> 0 | P45: =IF(B45=$E$6,0,I45+5*MIN(1,SUMPRODUCT(--ISNUMBER(SEARCH({" dias"," días","tiempo","demora","duraci","lead"," horas"},G45))))*(I45>0)) -> 0 | Q45: =IF(B45=$E$9,0,J45) -> 15.035 | R45: =IF(OR(B45=$E$6,INDEX($I$40:$I$79,MAX(1,$F$6))<12),0,O45) -> 0 | S45: =AND(C45>0,D45<0.5*C45,MIN(1,SUMPRODUCT(--ISNUMBER(SEARCH({"fecha","date","periodo","timestamp"},G45))))>0) -> FALSE
A46: 7 | B46: =IF(INDEX(Datos!$A$1:$AN$1,1,7)="","",INDEX(Datos!$A$1:$AN$1,1,7)&"") -> Etapa | C46: =IF(B46="",0,COUNTA(INDEX(Datos!$A$2:$AN$1048576,0,7))) -> 2400 | D46: =IF(B46="",0,COUNT(INDEX(Datos!$A$2:$AN$1048576,0,7))) -> 0 | E46: =AND(C46>0,D46>=0.9*C46,OR(LEFT(CELL("format",INDEX(Datos!$A$2:$AN$2,1,7)),1)="D",MIN(1,SUMPRODUCT(--ISNUMBER(SEARCH({"fecha","date","periodo","timestamp"},G46))))>0)) -> FALSE | F46: =AND(C46>0,D46>=0.9*C46,NOT(E46),MIN(1,SUMPRODUCT(--ISNUMBER(SEARCH({" id "," id"," cod"," nit "," cedula"," cédula"," telefono"," teléfono"," celular"," sku"," factura"," numero"," número"," nro"," año "," ano "," year"," zip"," postal"," documento"," guia"," guía"," orden"," cuenta"," pedido"," radicado"," consecutivo"," omr"," pob "," placa"," referencia"," ref "},G46))))=0,NOT(AND(K46>=20,K46>=0.95*MIN(500,C46),MIN(1,SUMPRODUCT(--ISNUMBER(SEARCH({"venta","ingreso","monto","importe","total","valor","factur","revenue","sales","amount","utilidad","ganancia","gasto"},G46))))+MIN(1,SUMPRODUCT(--ISNUMBER(SEARCH({"precio","price","unit","costo","cost","promedio","tasa","%","edad","calific","rating","puntaje","porcentaje","satisf","nps","score","nota"},G46))))+MIN(1,SUMPRODUCT(--ISNUMBER(SEARCH({"costo","cost"},G46))))+MIN(1,SUMPRODUCT(--ISNUMBER(SEARCH({" dias"," días","tiempo","demora","duraci","lead"," horas"},G46))))+MIN(1,SUMPRODUCT(--ISNUMBER(SEARCH({"cantidad","unidades","qty","peso","kilos"," kg","volumen","stock","existencia","inventario"},G46))))=0))) -> FALSE | G46: =" "&LOWER(SUBSTITUTE(SUBSTITUTE(SUBSTITUTE(B46,"_"," "),"-"," "),"."," "))&" " -> etapa | H46: =AND(C46>0,D46<0.5*C46) -> TRUE | I46: =IF(F46,2+10*MIN(1,SUMPRODUCT(--ISNUMBER(SEARCH({"venta","ingreso","monto","importe","total","valor","factur","revenue","sales","amount","utilidad","ganancia","gasto"},G46))))+8*MIN(1,SUMPRODUCT(--ISNUMBER(SEARCH({"cantidad","unidades","qty","peso","kilos"," kg","volumen","stock","existencia","inventario"},G46))))*(1-MIN(1,SUMPRODUCT(--ISNUMBER(SEARCH({"venta","ingreso","monto","importe","total","valor","factur","revenue","sales","amount","utilidad","ganancia","gasto"},G46)))))-MIN(1,SUMPRODUCT(--ISNUMBER(SEARCH({"precio","price","unit","costo","cost","promedio","tasa","%","edad","calific","rating","puntaje","porcentaje","satisf","nps","score","nota"},G46))))+0.034,0) -> 0 | J46: =IF(AND(H46,K46>=2),IF(K46<=40,2+10*MIN(1,SUMPRODUCT(--ISNUMBER(SEARCH({"categor","region","región","producto","linea","línea","segmento","canal","ciudad","tienda","sucursal","vendedor","cliente","tipo","marca","zona","sede","courier","transportadora","oficina","trayecto","motivo","clasifica","proceso"},G46))))+3*AND(K46>=4,K46<=25),0.5+MIN(1,SUMPRODUCT(--ISNUMBER(SEARCH({"categor","region","región","producto","linea","línea","segmento","canal","ciudad","tienda","sucursal","vendedor","cliente","tipo","marca","zona","sede","courier","transportadora","oficina","trayecto","motivo","clasifica","proceso"},G46)))))+0.034,0) -> 5.034 | K46: =IF(C46>0,SUMPRODUCT((INDEX(Datos!$A$2:$AN$501,0,7)<>"")/COUNTIF(INDEX(Datos!$A$2:$AN$501,0,7),INDEX(Datos!$A$2:$AN$501,0,7)&"")),0) -> 4 | L46: =IF(E46,1+MIN(1,SUMPRODUCT(--ISNUMBER(SEARCH({"fecha","date","periodo","timestamp"},G46))))+0.034,0) -> 0 | M46: =IF(AND(H46,K46>=2,K46<=15),MIN(1,SUMPRODUCT(--ISNUMBER(SEARCH({"etapa","fase","estado","stage","embudo","funnel","paso","status"},G46))))*(1+0.034),0) -> 1.034 | N46: =IF(H46,MIN(1,SUMPRODUCT(--ISNUMBER(SEARCH({"departamento","depto","dpto","depart"},G46))))*(1+0.034),0) -> 0 | O46: =IF(F46,MIN(1,SUMPRODUCT(--ISNUMBER(SEARCH({"costo","cost"},G46))))*(1+0.034),0) -> 0 | P46: =IF(B46=$E$6,0,I46+5*MIN(1,SUMPRODUCT(--ISNUMBER(SEARCH({" dias"," días","tiempo","demora","duraci","lead"," horas"},G46))))*(I46>0)) -> 0 | Q46: =IF(B46=$E$9,0,J46) -> 5.034 | R46: =IF(OR(B46=$E$6,INDEX($I$40:$I$79,MAX(1,$F$6))<12),0,O46) -> 0 | S46: =AND(C46>0,D46<0.5*C46,MIN(1,SUMPRODUCT(--ISNUMBER(SEARCH({"fecha","date","periodo","timestamp"},G46))))>0) -> FALSE
A47: 8 | B47: =IF(INDEX(Datos!$A$1:$AN$1,1,8)="","",INDEX(Datos!$A$1:$AN$1,1,8)&"") -> Unidades | C47: =IF(B47="",0,COUNTA(INDEX(Datos!$A$2:$AN$1048576,0,8))) -> 2400 | D47: =IF(B47="",0,COUNT(INDEX(Datos!$A$2:$AN$1048576,0,8))) -> 2400 | E47: =AND(C47>0,D47>=0.9*C47,OR(LEFT(CELL("format",INDEX(Datos!$A$2:$AN$2,1,8)),1)="D",MIN(1,SUMPRODUCT(--ISNUMBER(SEARCH({"fecha","date","periodo","timestamp"},G47))))>0)) -> FALSE | F47: =AND(C47>0,D47>=0.9*C47,NOT(E47),MIN(1,SUMPRODUCT(--ISNUMBER(SEARCH({" id "," id"," cod"," nit "," cedula"," cédula"," telefono"," teléfono"," celular"," sku"," factura"," numero"," número"," nro"," año "," ano "," year"," zip"," postal"," documento"," guia"," guía"," orden"," cuenta"," pedido"," radicado"," consecutivo"," omr"," pob "," placa"," referencia"," ref "},G47))))=0,NOT(AND(K47>=20,K47>=0.95*MIN(500,C47),MIN(1,SUMPRODUCT(--ISNUMBER(SEARCH({"venta","ingreso","monto","importe","total","valor","factur","revenue","sales","amount","utilidad","ganancia","gasto"},G47))))+MIN(1,SUMPRODUCT(--ISNUMBER(SEARCH({"precio","price","unit","costo","cost","promedio","tasa","%","edad","calific","rating","puntaje","porcentaje","satisf","nps","score","nota"},G47))))+MIN(1,SUMPRODUCT(--ISNUMBER(SEARCH({"costo","cost"},G47))))+MIN(1,SUMPRODUCT(--ISNUMBER(SEARCH({" dias"," días","tiempo","demora","duraci","lead"," horas"},G47))))+MIN(1,SUMPRODUCT(--ISNUMBER(SEARCH({"cantidad","unidades","qty","peso","kilos"," kg","volumen","stock","existencia","inventario"},G47))))=0))) -> TRUE | G47: =" "&LOWER(SUBSTITUTE(SUBSTITUTE(SUBSTITUTE(B47,"_"," "),"-"," "),"."," "))&" " -> unidades | H47: =AND(C47>0,D47<0.5*C47) -> FALSE | I47: =IF(F47,2+10*MIN(1,SUMPRODUCT(--ISNUMBER(SEARCH({"venta","ingreso","monto","importe","total","valor","factur","revenue","sales","amount","utilidad","ganancia","gasto"},G47))))+8*MIN(1,SUMPRODUCT(--ISNUMBER(SEARCH({"cantidad","unidades","qty","peso","kilos"," kg","volumen","stock","existencia","inventario"},G47))))*(1-MIN(1,SUMPRODUCT(--ISNUMBER(SEARCH({"venta","ingreso","monto","importe","total","valor","factur","revenue","sales","amount","utilidad","ganancia","gasto"},G47)))))-MIN(1,SUMPRODUCT(--ISNUMBER(SEARCH({"precio","price","unit","costo","cost","promedio","tasa","%","edad","calific","rating","puntaje","porcentaje","satisf","nps","score","nota"},G47))))+0.033,0) -> 10.033 | J47: =IF(AND(H47,K47>=2),IF(K47<=40,2+10*MIN(1,SUMPRODUCT(--ISNUMBER(SEARCH({"categor","region","región","producto","linea","línea","segmento","canal","ciudad","tienda","sucursal","vendedor","cliente","tipo","marca","zona","sede","courier","transportadora","oficina","trayecto","motivo","clasifica","proceso"},G47))))+3*AND(K47>=4,K47<=25),0.5+MIN(1,SUMPRODUCT(--ISNUMBER(SEARCH({"categor","region","región","producto","linea","línea","segmento","canal","ciudad","tienda","sucursal","vendedor","cliente","tipo","marca","zona","sede","courier","transportadora","oficina","trayecto","motivo","clasifica","proceso"},G47)))))+0.033,0) -> 0 | K47: =IF(C47>0,SUMPRODUCT((INDEX(Datos!$A$2:$AN$501,0,8)<>"")/COUNTIF(INDEX(Datos!$A$2:$AN$501,0,8),INDEX(Datos!$A$2:$AN$501,0,8)&"")),0) -> 5 | L47: =IF(E47,1+MIN(1,SUMPRODUCT(--ISNUMBER(SEARCH({"fecha","date","periodo","timestamp"},G47))))+0.033,0) -> 0 | M47: =IF(AND(H47,K47>=2,K47<=15),MIN(1,SUMPRODUCT(--ISNUMBER(SEARCH({"etapa","fase","estado","stage","embudo","funnel","paso","status"},G47))))*(1+0.033),0) -> 0 | N47: =IF(H47,MIN(1,SUMPRODUCT(--ISNUMBER(SEARCH({"departamento","depto","dpto","depart"},G47))))*(1+0.033),0) -> 0 | O47: =IF(F47,MIN(1,SUMPRODUCT(--ISNUMBER(SEARCH({"costo","cost"},G47))))*(1+0.033),0) -> 0 | P47: =IF(B47=$E$6,0,I47+5*MIN(1,SUMPRODUCT(--ISNUMBER(SEARCH({" dias"," días","tiempo","demora","duraci","lead"," horas"},G47))))*(I47>0)) -> 10.033 | Q47: =IF(B47=$E$9,0,J47) -> 0 | R47: =IF(OR(B47=$E$6,INDEX($I$40:$I$79,MAX(1,$F$6))<12),0,O47) -> 0 | S47: =AND(C47>0,D47<0.5*C47,MIN(1,SUMPRODUCT(--ISNUMBER(SEARCH({"fecha","date","periodo","timestamp"},G47))))>0) -> FALSE
A48: 9 | B48: =IF(INDEX(Datos!$A$1:$AN$1,1,9)="","",INDEX(Datos!$A$1:$AN$1,1,9)&"") -> Precio unitario | C48: =IF(B48="",0,COUNTA(INDEX(Datos!$A$2:$AN$1048576,0,9))) -> 2400 | D48: =IF(B48="",0,COUNT(INDEX(Datos!$A$2:$AN$1048576,0,9))) -> 2400 | E48: =AND(C48>0,D48>=0.9*C48,OR(LEFT(CELL("format",INDEX(Datos!$A$2:$AN$2,1,9)),1)="D",MIN(1,SUMPRODUCT(--ISNUMBER(SEARCH({"fecha","date","periodo","timestamp"},G48))))>0)) -> FALSE | F48: =AND(C48>0,D48>=0.9*C48,NOT(E48),MIN(1,SUMPRODUCT(--ISNUMBER(SEARCH({" id "," id"," cod"," nit "," cedula"," cédula"," telefono"," teléfono"," celular"," sku"," factura"," numero"," número"," nro"," año "," ano "," year"," zip"," postal"," documento"," guia"," guía"," orden"," cuenta"," pedido"," radicado"," consecutivo"," omr"," pob "," placa"," referencia"," ref "},G48))))=0,NOT(AND(K48>=20,K48>=0.95*MIN(500,C48),MIN(1,SUMPRODUCT(--ISNUMBER(SEARCH({"venta","ingreso","monto","importe","total","valor","factur","revenue","sales","amount","utilidad","ganancia","gasto"},G48))))+MIN(1,SUMPRODUCT(--ISNUMBER(SEARCH({"precio","price","unit","costo","cost","promedio","tasa","%","edad","calific","rating","puntaje","porcentaje","satisf","nps","score","nota"},G48))))+MIN(1,SUMPRODUCT(--ISNUMBER(SEARCH({"costo","cost"},G48))))+MIN(1,SUMPRODUCT(--ISNUMBER(SEARCH({" dias"," días","tiempo","demora","duraci","lead"," horas"},G48))))+MIN(1,SUMPRODUCT(--ISNUMBER(SEARCH({"cantidad","unidades","qty","peso","kilos"," kg","volumen","stock","existencia","inventario"},G48))))=0))) -> TRUE | G48: =" "&LOWER(SUBSTITUTE(SUBSTITUTE(SUBSTITUTE(B48,"_"," "),"-"," "),"."," "))&" " -> precio unitario | H48: =AND(C48>0,D48<0.5*C48) -> FALSE | I48: =IF(F48,2+10*MIN(1,SUMPRODUCT(--ISNUMBER(SEARCH({"venta","ingreso","monto","importe","total","valor","factur","revenue","sales","amount","utilidad","ganancia","gasto"},G48))))+8*MIN(1,SUMPRODUCT(--ISNUMBER(SEARCH({"cantidad","unidades","qty","peso","kilos"," kg","volumen","stock","existencia","inventario"},G48))))*(1-MIN(1,SUMPRODUCT(--ISNUMBER(SEARCH({"venta","ingreso","monto","importe","total","valor","factur","revenue","sales","amount","utilidad","ganancia","gasto"},G48)))))-MIN(1,SUMPRODUCT(--ISNUMBER(SEARCH({"precio","price","unit","costo","cost","promedio","tasa","%","edad","calific","rating","puntaje","porcentaje","satisf","nps","score","nota"},G48))))+0.032,0) -> 1.032 | J48: =IF(AND(H48,K48>=2),IF(K48<=40,2+10*MIN(1,SUMPRODUCT(--ISNUMBER(SEARCH({"categor","region","región","producto","linea","línea","segmento","canal","ciudad","tienda","sucursal","vendedor","cliente","tipo","marca","zona","sede","courier","transportadora","oficina","trayecto","motivo","clasifica","proceso"},G48))))+3*AND(K48>=4,K48<=25),0.5+MIN(1,SUMPRODUCT(--ISNUMBER(SEARCH({"categor","region","región","producto","linea","línea","segmento","canal","ciudad","tienda","sucursal","vendedor","cliente","tipo","marca","zona","sede","courier","transportadora","oficina","trayecto","motivo","clasifica","proceso"},G48)))))+0.032,0) -> 0 | K48: =IF(C48>0,SUMPRODUCT((INDEX(Datos!$A$2:$AN$501,0,9)<>"")/COUNTIF(INDEX(Datos!$A$2:$AN$501,0,9),INDEX(Datos!$A$2:$AN$501,0,9)&"")),0) -> 466 | L48: =IF(E48,1+MIN(1,SUMPRODUCT(--ISNUMBER(SEARCH({"fecha","date","periodo","timestamp"},G48))))+0.032,0) -> 0 | M48: =IF(AND(H48,K48>=2,K48<=15),MIN(1,SUMPRODUCT(--ISNUMBER(SEARCH({"etapa","fase","estado","stage","embudo","funnel","paso","status"},G48))))*(1+0.032),0) -> 0 | N48: =IF(H48,MIN(1,SUMPRODUCT(--ISNUMBER(SEARCH({"departamento","depto","dpto","depart"},G48))))*(1+0.032),0) -> 0 | O48: =IF(F48,MIN(1,SUMPRODUCT(--ISNUMBER(SEARCH({"costo","cost"},G48))))*(1+0.032),0) -> 0 | P48: =IF(B48=$E$6,0,I48+5*MIN(1,SUMPRODUCT(--ISNUMBER(SEARCH({" dias"," días","tiempo","demora","duraci","lead"," horas"},G48))))*(I48>0)) -> 1.032 | Q48: =IF(B48=$E$9,0,J48) -> 0 | R48: =IF(OR(B48=$E$6,INDEX($I$40:$I$79,MAX(1,$F$6))<12),0,O48) -> 0 | S48: =AND(C48>0,D48<0.5*C48,MIN(1,SUMPRODUCT(--ISNUMBER(SEARCH({"fecha","date","periodo","timestamp"},G48))))>0) -> FALSE
A49: 10 | B49: =IF(INDEX(Datos!$A$1:$AN$1,1,10)="","",INDEX(Datos!$A$1:$AN$1,1,10)&"") -> Ventas | C49: =IF(B49="",0,COUNTA(INDEX(Datos!$A$2:$AN$1048576,0,10))) -> 2400 | D49: =IF(B49="",0,COUNT(INDEX(Datos!$A$2:$AN$1048576,0,10))) -> 2400 | E49: =AND(C49>0,D49>=0.9*C49,OR(LEFT(CELL("format",INDEX(Datos!$A$2:$AN$2,1,10)),1)="D",MIN(1,SUMPRODUCT(--ISNUMBER(SEARCH({"fecha","date","periodo","timestamp"},G49))))>0)) -> FALSE | F49: =AND(C49>0,D49>=0.9*C49,NOT(E49),MIN(1,SUMPRODUCT(--ISNUMBER(SEARCH({" id "," id"," cod"," nit "," cedula"," cédula"," telefono"," teléfono"," celular"," sku"," factura"," numero"," número"," nro"," año "," ano "," year"," zip"," postal"," documento"," guia"," guía"," orden"," cuenta"," pedido"," radicado"," consecutivo"," omr"," pob "," placa"," referencia"," ref "},G49))))=0,NOT(AND(K49>=20,K49>=0.95*MIN(500,C49),MIN(1,SUMPRODUCT(--ISNUMBER(SEARCH({"venta","ingreso","monto","importe","total","valor","factur","revenue","sales","amount","utilidad","ganancia","gasto"},G49))))+MIN(1,SUMPRODUCT(--ISNUMBER(SEARCH({"precio","price","unit","costo","cost","promedio","tasa","%","edad","calific","rating","puntaje","porcentaje","satisf","nps","score","nota"},G49))))+MIN(1,SUMPRODUCT(--ISNUMBER(SEARCH({"costo","cost"},G49))))+MIN(1,SUMPRODUCT(--ISNUMBER(SEARCH({" dias"," días","tiempo","demora","duraci","lead"," horas"},G49))))+MIN(1,SUMPRODUCT(--ISNUMBER(SEARCH({"cantidad","unidades","qty","peso","kilos"," kg","volumen","stock","existencia","inventario"},G49))))=0))) -> TRUE | G49: =" "&LOWER(SUBSTITUTE(SUBSTITUTE(SUBSTITUTE(B49,"_"," "),"-"," "),"."," "))&" " -> ventas | H49: =AND(C49>0,D49<0.5*C49) -> FALSE | I49: =IF(F49,2+10*MIN(1,SUMPRODUCT(--ISNUMBER(SEARCH({"venta","ingreso","monto","importe","total","valor","factur","revenue","sales","amount","utilidad","ganancia","gasto"},G49))))+8*MIN(1,SUMPRODUCT(--ISNUMBER(SEARCH({"cantidad","unidades","qty","peso","kilos"," kg","volumen","stock","existencia","inventario"},G49))))*(1-MIN(1,SUMPRODUCT(--ISNUMBER(SEARCH({"venta","ingreso","monto","importe","total","valor","factur","revenue","sales","amount","utilidad","ganancia","gasto"},G49)))))-MIN(1,SUMPRODUCT(--ISNUMBER(SEARCH({"precio","price","unit","costo","cost","promedio","tasa","%","edad","calific","rating","puntaje","porcentaje","satisf","nps","score","nota"},G49))))+0.031,0) -> 12.031 | J49: =IF(AND(H49,K49>=2),IF(K49<=40,2+10*MIN(1,SUMPRODUCT(--ISNUMBER(SEARCH({"categor","region","región","producto","linea","línea","segmento","canal","ciudad","tienda","sucursal","vendedor","cliente","tipo","marca","zona","sede","courier","transportadora","oficina","trayecto","motivo","clasifica","proceso"},G49))))+3*AND(K49>=4,K49<=25),0.5+MIN(1,SUMPRODUCT(--ISNUMBER(SEARCH({"categor","region","región","producto","linea","línea","segmento","canal","ciudad","tienda","sucursal","vendedor","cliente","tipo","marca","zona","sede","courier","transportadora","oficina","trayecto","motivo","clasifica","proceso"},G49)))))+0.031,0) -> 0 | K49: =IF(C49>0,SUMPRODUCT((INDEX(Datos!$A$2:$AN$501,0,10)<>"")/COUNTIF(INDEX(Datos!$A$2:$AN$501,0,10),INDEX(Datos!$A$2:$AN$501,0,10)&"")),0) -> 491 | L49: =IF(E49,1+MIN(1,SUMPRODUCT(--ISNUMBER(SEARCH({"fecha","date","periodo","timestamp"},G49))))+0.031,0) -> 0 | M49: =IF(AND(H49,K49>=2,K49<=15),MIN(1,SUMPRODUCT(--ISNUMBER(SEARCH({"etapa","fase","estado","stage","embudo","funnel","paso","status"},G49))))*(1+0.031),0) -> 0 | N49: =IF(H49,MIN(1,SUMPRODUCT(--ISNUMBER(SEARCH({"departamento","depto","dpto","depart"},G49))))*(1+0.031),0) -> 0 | O49: =IF(F49,MIN(1,SUMPRODUCT(--ISNUMBER(SEARCH({"costo","cost"},G49))))*(1+0.031),0) -> 0 | P49: =IF(B49=$E$6,0,I49+5*MIN(1,SUMPRODUCT(--ISNUMBER(SEARCH({" dias"," días","tiempo","demora","duraci","lead"," horas"},G49))))*(I49>0)) -> 0 | Q49: =IF(B49=$E$9,0,J49) -> 0 | R49: =IF(OR(B49=$E$6,INDEX($I$40:$I$79,MAX(1,$F$6))<12),0,O49) -> 0 | S49: =AND(C49>0,D49<0.5*C49,MIN(1,SUMPRODUCT(--ISNUMBER(SEARCH({"fecha","date","periodo","timestamp"},G49))))>0) -> FALSE
